Workbook

Sheet ① 기초Data
A1: 화학물질 위험성평가
A2: MSDS 데이터 기반 | 물리화학적 · 환경오염 · 작업자 안전보건 | 유해성(강도) × 가능성(빈도)
B4: 1. 평가 대상 화학물질 기본정보 | G4: ▼ 작성 Guide
B5: 제품명 | G5: MSDS 세션1
B6: 제조사
B7: MSDS 최신개정일자 | G7: MSDS 첫페이지 상단 또는 세션16
B8: 구성성분 *물(Water) 생략 가능, 필요시 행 추가 | C8: 물질명 | D8: CAS No. | E8: 함량 (%) | G8: MSDS 세션3 (가장 높은 함량 순으로 상위에 기재)
B14: 취급부서 / 공정 | G14: 사업장 취급현황에 맞게 작성
B15: 저장·보관(예정) 장소
B16: 도입 배경or목적 | H16: ▼ 연관 평가항목 (위험성평가 어느 항목에 사용되는지)
B17: ★H-Code (유해위험문구) | G17: MSDS 세션2. H코드 전체 입력 쉼표(,) 또는 공백( )으로 코드 구분 ★H314 / H340 / H350 / H360의 경우, Cat(구분) 표기까지 정확히 포함하여 입력 [예시] 'H350 Cat1A' 또는 'H350 Cat1B' (띄어쓰기 유의!) | H17: ①기본데이터 입력 Sheet - 2. MSDS 세션별 데이터 입력 Sec.2와 수식 연계된 항목으로 정확히 입력 필요
B19: 2. MSDS 세션별 데이터 입력
B20: 📌 입력 방법 - 초록색 셀(D열)은 17행 H-Code 입력 내용과 수식으로 연동 되어, 별도 입력하지 않습니다. (17행 H-Code 정확히 입력 要) - 노란색 셀(D열)은 MSDS에서 확인한 값을 직접 입력하세요. 숫자 셀은 숫자만, 선택 셀은 드롭다운(▼)에서 선택하세요. - 값이 없거나 해당 없으면 '없음'을 선택하거나 입력하세요. (빈칸으로 두면 숫자 '0'으로 인식되어 위험성평가 오류 발생) ★ 이 시트의 값이 각 ②~④ 위험성 평가Sheet의 E열과 자동 연동됩니다. (우측 H열의 '연관 평가항목' 참고)
B21: 구분 | C21: 입력 항목 | D21: ★입력란 | E21: 비고 (단위 등)
B22: ▶ Sec 2 — 유해·위험 문구 (H-Code) | G22: ▼ 작성 Guide | H22: ▼ 연관 평가항목 (위험성평가 어느 항목에 사용되는지)
B23: 인화성 | C23: • H220: 인화한계 하한(LFL)≤13% 또는 연소범위≥12% (극인화성 가스) • H221: H220 기준 미달 (인화성 가스) • H222: 인화점<23°C 에어로졸 (극인화성 에어로졸) • H223: 인화점23~60°C 에어로졸 (인화성 에어로졸) • H224: 인화점<23°C 및 끓는점≤35°C (극인화성 액체·증기) • H225: 인화점<23°C 및 끓는점>35°C (고인화성 액체·증기) • H226: 인화점23~60°C (인화성 액체·증기) • H227: 인화점60~93°C (가연성 액체) • H228: 연소시간≤45초 또는 연소속도≥76mm/min (인화성 고체) | D23: {=IFERROR(INDEX('(수정금지) 기준정보'!$D$5:$D$13,MATCH(1,ISNUMBER(SEARCH('(수정금지) 기준정보'!$D$5:$D$13,C17))*1,0)),"없음")} -> 없음 | E23: 수식으로 자동 입력 | G23: Sec2 그림문자·H코드 확인 → 17행에 입력한 H-Code 자동 연계 | H23: 【②-7 인화성 등급】 5점 : H220, H221, H222, H224 4점 : H223, H225 3점 : H226, H228 2점 : H227 ★Sec9 인화점(45행)과 함께 최종 판단
B24: 폭발성 | C24: • H200~H205: 폭발성 1.1~1.5류 • H206: 자기반응성/유기과산화물 TypeB • H207: TypeC/D • H208: TypeE/F • H240: 가열하면 폭발할 수 있음 • H241: 가열하면 화재 또는 폭발할 수 있음 • H242: 가열하면 화재를 일으킬 수 있음 | D24: {=IFERROR(INDEX('(수정금지) 기준정보'!$D$20:$D$31,MATCH(1,ISNUMBER(SEARCH('(수정금지) 기준정보'!$D$20:$D$31,C17))*1,0)),"없음")} -> 없음 | E24: 수식으로 자동 입력 | G24: " | H24: 【②-5 불안정성】 & 【②-8 폭발성·산화성】 5점 : H200~H205 4점 : H206, H240 3점 : H207, H241 2점 : H208, H242 ★Sec10 분해온도(53행)와 함께 최종 판단
B25: 산화성 | C25: • H270: 극강산화성 Cat1 • H271: 강산화성 Cat1 • H272: 가연물 화재 촉진 Cat2,3 | D25: {=IFERROR(INDEX('(수정금지) 기준정보'!$D$43:$D$45,MATCH(1,ISNUMBER(SEARCH('(수정금지) 기준정보'!$D$43:$D$45,C17))*1,0)),"없음")} -> 없음 | E25: 수식으로 자동 입력 | G25: " | H25: 【②-8 폭발성·산화성】 5점 : H270 4점 : H271 3점 : H272
B26: 물 반응성 | C26: • H260: 물과 접촉 시 자연발화성 가스 발생 • H261: 물과 접촉 시 인화성 가스 발생 | D26: {=IFERROR(INDEX('(수정금지) 기준정보'!$D$47:$D$48,MATCH(1,ISNUMBER(SEARCH('(수정금지) 기준정보'!$D$47:$D$48,C17))*1,0)),"없음")} -> 없음 | E26: 수식으로 자동 입력 | G26: " | H26: 【②-1 물·산·염기 접촉】 5점 : H260 5점 : H261 ★Sec10 물반응 정도(51행)와 함께 최종 판단
B27: 금속부식성 | C27: • H290: 금속부식성 물질 | D27: =IFERROR(IF(ISNUMBER(SEARCH('(수정금지) 기준정보'!$D$49,C17)),'(수정금지) 기준정보'!$D$49,"없음"),"없음") -> 없음 | E27: 수식으로 자동 입력 | G27: " | H27: 【②-1 물·산·염기 접촉】 4점 : H290 ★Sec10 물반응 정도(51행)와 함께 최종 판단
B28: 자연발화·자기발열 | C28: • H250: 공기접촉 즉시 자연발화 • H251: 대량에서 자기발열·화재 (Cat1) • H252: 대량에서 자기발열·화재 (Cat2) | D28: {=IFERROR(INDEX('(수정금지) 기준정보'!$D$55:$D$57,MATCH(1,ISNUMBER(SEARCH('(수정금지) 기준정보'!$D$55:$D$57,C17))*1,0)),"없음")} -> 없음 | E28: 수식으로 자동 입력 | G28: " | H28: 【②-2 공기·수분 반응·자연발화】 5점 : H250 4점 : H251 3점 : H252 ★Sec9 자연발화온도(47행)와 함께 최종 판단
B29: 급성독성 흡입 | C29: • H330: 흡입 시 치명 (Cat1~2) • H331: 흡입 시 독성 (Cat3) • H332: 흡입 시 유해 (Cat4) | D29: {=IFERROR(INDEX('(수정금지) 기준정보'!$D$62:$D$64,MATCH(1,ISNUMBER(SEARCH('(수정금지) 기준정보'!$D$62:$D$64,C17))*1,0)),"없음")} -> 없음 | E29: 수식으로 자동 입력 | G29: " | H29: 【④-1 흡입독성】 5점 : H330 4점 : H331 3점 : H332 2점 : H333 ★Sec11 흡입독성 LC50(56,57행)과 함께 최종 판단
B30: 급성독성 경구·경피 | C30: • H300: 삼키면 치명 (Cat1~2) • H301: 삼키면 독성 (Cat3) • H302: 삼키면 유해 (Cat4) • H304: 삼켜서 기도로 유입되면 치명 (Cat1) • H305: 삼켜서 기도로 유입되면 유해 (Cat2) • H310: 피부와 접촉하면 치명 (Cat1~2) • H311: 피부와 접촉하면 독성 (Cat3) • H312: 피부와 접촉하면 유해 (Cat4) | D30: {=IFERROR(INDEX('(수정금지) 기준정보'!$D$77:$D$84,MATCH(1,ISNUMBER(SEARCH('(수정금지) 기준정보'!$D$77:$D$84,C17))*1,0)),"없음")} -> 없음 | E30: 수식으로 자동 입력 | G30: " | H30: 【④-2 경구·경피독성】 5점 : H300, H310 4점 : H301, H304, H311 3점 : H305 2점 : H302, H312 ★Sec11 경구LD50(58행), 경피LD50(59행)과 함께 최종 판단
B31: 피부 부식성·자극성 | C31: • H314 Cat1A: 즉각 피부 부식 • H314 Cat1/1B: 4시간 내 피부 부식 (Cat1) • H315: 피부 자극성 (Cat2) • H316: 경미한 피부 자극 (Cat3) • H317: 피부 과민성(감작성) (Cat1) | D31: {=IFERROR(INDEX('(수정금지) 기준정보'!$D$96:$D$101,MATCH(1,ISNUMBER(SEARCH('(수정금지) 기준정보'!$D$96:$D$101,C17))*1,0)),"없음")} -> 없음 | E31: 수식으로 자동 입력 | G31: " | H31: 【④-3 피부·눈 자극성 및 부식성】 5점 : H314 Cat1A 4점 : H314 Cat1 / Cat1B 3점 : H315, H317 2점 : H316
B32: 눈 손상·자극성 | C32: • H318: 비가역적 눈 손상 (Cat1) • H319: 가역적 눈 자극 (Cat2) • H320: 경미한 눈 자극 (Cat3) | D32: {=IFERROR(INDEX('(수정금지) 기준정보'!$D$102:$D$104,MATCH(1,ISNUMBER(SEARCH('(수정금지) 기준정보'!$D$102:$D$104,C17))*1,0)),"없음")} -> 없음 | E32: 수식으로 자동 입력 | G32: " | H32: 【④-3 피부·눈 자극성 및 부식성】 4점: H318 3점: H319 2점: H320
B33: 발암성 | C33: • H350 Cat1A: 발암 확인 (IARC 1) • H350 Cat1B: 발암 추정 • H351: 발암 의심 (Cat2) | D33: {=IFERROR(INDEX('(수정금지) 기준정보'!$D$106:$D$108,MATCH(1,ISNUMBER(SEARCH('(수정금지) 기준정보'!$D$106:$D$108,C17))*1,0)),"없음")} -> 없음 | E33: 수식으로 자동 입력 | G33: " | H33: 【④-4 발암성】 5점 : H350 Cat1A 4점 : H350 Cat1B 3점 : H351 ★Sec11 IARC Group(60행)과 함께 최종 판단
B34: 생식독성 | C34: • H360 Cat1A: 생식독성 확인 • H360 Cat1B: 생식독성 추정 • H361: 생식독성 의심 • H362: 수유독성 | D34: {=IFERROR(INDEX('(수정금지) 기준정보'!$D$114:$D$117,MATCH(1,ISNUMBER(SEARCH('(수정금지) 기준정보'!$D$114:$D$117,C17))*1,0)),"없음")} -> 없음 | E34: 수식으로 자동 입력 | G34: " | H34: 【④-5 생식·발달독성】 5점 : H360 Cat1A 4점 : H360 Cat1B 3점 : H361 2점: H362
B35: STOT 반복독성 | C35: • H370: 1회 노출 — 장기 손상 확인 • H371: 1회 노출 — 장기 손상 가능 • H372: 반복 노출 — 장기 손상 확인 • H373: 반복 노출 — 장기 손상 가능 | D35: {=IFERROR(INDEX('(수정금지) 기준정보'!$D$119:$D$122,MATCH(1,ISNUMBER(SEARCH('(수정금지) 기준정보'!$D$119:$D$122,C17))*1,0)),"없음")} -> 없음 | E35: 수식으로 자동 입력 | G35: " | H35: 【④-6 STOT(특정표적장기독성) 및 호흡기 과민성】 5점 : H370 4점 : H371 3점 : H372 2점 : H373
B36: 호흡기 과민성 | C36: • H334: 호흡기 과민성 Cat1 • H335: 호흡기 자극성 • H336: 마취성 | D36: {=IFERROR(INDEX('(수정금지) 기준정보'!$D$123:$D$125,MATCH(1,ISNUMBER(SEARCH('(수정금지) 기준정보'!$D$123:$D$125,C17))*1,0)),"없음")} -> 없음 | E36: 수식으로 자동 입력 | G36: " | H36: 【④-6 STOT(특정표적장기독성) 및 호흡기 과민성】 4점 : H334 3점 : H335 2점 : H336
B37: 변이원성 | C37: • H340 Cat1A: 변이원성 확인 • H340 Cat1B: 변이원성 추정 • H341: 변이원성 의심 | D37: {=IFERROR(INDEX('(수정금지) 기준정보'!$D$127:$D$129,MATCH(1,ISNUMBER(SEARCH('(수정금지) 기준정보'!$D$127:$D$129,C17))*1,0)),"없음")} -> 없음 | E37: 수식으로 자동 입력 | G37: " | H37: 【④-7 변이원성】 5점 : H340 Cat1A 4점 : H340 Cat1B 3점 : H341
B38: 수생 급성독성 | C38: • H400: 수생 급성 Cat1 (LC50≤1mg/L) • H401: 수생 급성 Cat2 • H402: 수생 급성 Cat3 | D38: {=IFERROR(INDEX('(수정금지) 기준정보'!$D$142:$D$144,MATCH(1,ISNUMBER(SEARCH('(수정금지) 기준정보'!$D$142:$D$144,C17))*1,0)),"없음")} -> 없음 | E38: 수식으로 자동 입력 | G38: " | H38: 【③-1 수생 생물 급성독성】 5점 : H400 4점 : H401 3점 : H402 ★Sec12 어류LC50, 물벼룩/갑각류EC50(61,62행)과 함께 최종 판단
B39: 수생 만성독성 | C39: • H410: 수생 만성 Cat1 • H411: 수생 만성 Cat2 • H412: 수생 만성 Cat3 • H413: 수생 만성 Cat4 | D39: {=IFERROR(INDEX('(수정금지) 기준정보'!$D$151:$D$154,MATCH(1,ISNUMBER(SEARCH('(수정금지) 기준정보'!$D$151:$D$154,C17))*1,0)),"없음")} -> 없음 | E39: 수식으로 자동 입력 | G39: " | H39: 【③-2 수생 생물 만성독성】 5점 : H410 4점 : H411 3점 : H412 2점 : H413
B40: 오존층 파괴 | C40: • H420 : 오존층 파괴 물질(ODS) | D40: =IFERROR(IF(ISNUMBER(SEARCH('(수정금지) 기준정보'!$D$203,C17)),'(수정금지) 기준정보'!$D$203,"없음"),"없음") -> 없음 | E40: 수식으로 자동 입력 | G40: " | H40: 【③-8 대기오염 영향 (VOC, ODS)】 5점 : H420 ★Sec9 증기압(48행)으로 VOC 수준과 함께 최종 판단
B41: ▶ Sec 8 — 노출기준 (TWA)
B42: 작업환경 노출기준 TWA (mg/m³) | C42: 국내 노출기준 TWA(mg/m³) 확인 숫자만 입력 (단위 주의), 없으면 '없음' 입력 | E42: mg/m³ | G42: Sec8에서 노출기준 TWA(mg/m³) 확인 없으면 '없음' 예) 황산: 0.2 톨루엔: 188 아세톤: 1,200 | H42: 【④-8 작업환경 노출기준(TWA)】 단위가 mg/m³인 경우, TWA 수치 낮을수록 위험↑ ≥100=1점, 10~100=2점, 1~10=3점, 0.1~1=4점, <0.1=5점
B43: 작업환경 노출기준 TWA (ppm) | C43: mg/m³와 병기시 ppm값도 입력. 숫자만 입력 (단위 주의), 없으면 '없음' 입력 | E43: ppm | G43: mg/m³와 병기시 ppm값도 입력. 없으면 '없음' 예) 황산: 없음 톨루엔: 50 아세톤: 500 | H43: 【④-8 작업환경 노출기준(TWA)】 단위가 ppm인 경우, ≥50=1점, 5~50=2점, 0.5~5=3점, 0.05~0.5=4점, <0.05=5점
B44: ▶ Sec 9 — 물리화학적 특성
B45: 인화점 (Flash Point) | C45: 숫자만 입력 (단위 주의), 없으면 '없음' 입력 | E45: °C | G45: 숫자 입력. 인화점 없으면 '없음' 입력 예) 아세톤: -20 에탄올: 13 황산: 없음 | H45: 【②-7 인화성】 인화점 수치로 인화성 등급 판정
B46: 끓는점 (Boiling Point) | C46: 숫자만 입력 (단위 주의), 없으면 '없음' 입력 | E46: °C | G46: 숫자 입력. 없으면 '없음' 예) 황산(96%): 330 아세톤: 56 | H46: 【②-7 인화성】 인화성 4,5점 판정 시 적용
B47: 자연발화온도 (AIT; Auto Ignition Temperature) | C47: 숫자만 입력 (단위 주의), 없으면 '없음' 입력 | E47: °C | G47: 숫자 입력. 없으면 '없음' 예) 에탄올: 365 아세톤: 465 | H47: 【②-2 공기·수분 반응·자연발화】 AIT <54°C → 5점, <100°C → 4점, <200°C → 3점
...

Sheet ② 물리화학적 위험성
A1: 물리화학적 위험성
A2: Physical & Chemical Hazard | 반응성·부산물·불안정성·화재·폭발
B4: Ⅰ. 유해성 산정
B5: 1) 8개의 유해성 평가항목별 유해성 점수(F열, 노란색 셀)를 입력하세요. - '[참고값] 유해성'(E열)은 '①기초Data'Sheet와 연동되어 유해성(1~5점)을 제시합니다. 해당 값을 참고하여 진행하시고, 만일 [참고값]과 다르게 유해성을 입력하는 경우, '비고'(M열)에 다르게 평가한 사유 기재 要 2) 8개의 유해성 평가항목을 모두 입력한 후, 산정된 유해성 등급(20행, 1~5등급)을 확인하세요.
B6: No. | C6: 구분 | D6: 평가 항목 | E6: [참고값] 유해성 (①기초Data 연동) | F6: ▶유해성 입력 (1~5) | G6: 평가 기준 | M6: 비고
G7: MSDS 확인 항목 | H7: 1점 (미미) | I7: 2점 (경미) | J7: 3점 (보통) | K7: 4점 (중대) | L7: 5점 (치명) | O7: [참고] 유해성 기준 출처 및 배경
B8: 1 | C8: 반응성 | D8: 물·산·염기와의 접촉 반응성 (발열, 가스 발생 등) | E8: =IFERROR(MAX(IF(OR('① 기초Data'!D26="H260",'① 기초Data'!D26="H261"),5,IF('① 기초Data'!D27="H290",4,IF('① 기초Data'!D51='(수정금지) 기준정보'!E50,4,IF('① 기초Data'!D51='(수정금지) 기준정보'!E51,3,IF('① 기초Data'!D51='(수정금지) 기준정보'!E52,2,1)))))),"?") -> 1 | G8: 1. Sec2 H260,H261,H290 2. Sec10 물반응 | H8: 반응 없음 H260/261/290 없음 물·산·염기 비반응 | I8: 미약한 발열 ΔT<10°C | J8: 중등도 반응 ΔT10~50°C | K8: 격렬한 반응 ΔT>50°C 또는 H290 (금속부식성 물질) | L8: 폭발적 반응 H260, H261 (자연발화성/인화성 가스 발생) | O8: 근거: GHS 수반응성 분류 + 화학물질관리법 ▸ 주요 출처 ① 환경부 고시 제2023-2호 「화학물질의 분류·표시에 관한 규정」 H260(자연발화성 가스), H261(인화성가스), H290(금속부식성) 코드 정의 ② UN GHS(Globally Harmonized System) 제9개정판(2021) Part 3 수반응성 물질 분류 기준 (Cat.1/2 및 반응 발열량) ③ 소방청 「위험물안전관리법 시행령」 별표1 금수성 물질 분류 기준 ▸ 점수 구간 설정 배경 반응 시 온도 변화(ΔT)는 KOSHA GUIDE W-23-2020 「화학물질 반응 위험성 평가」 중증도 구간(ΔT 10·50°C)을 준용함
B9: 2 | C9: 반응성 | D9: 공기·수분 반응·자연발화 (흡습 발열, 자기발화) | E9: =IFERROR(MAX(IF('① 기초Data'!D28="H250",5,IF('① 기초Data'!D28="H251",4,IF('① 기초Data'!D28="H252",3,1))), IF('① 기초Data'!D47<54,5,IF('① 기초Data'!D47<100,4, IF('① 기초Data'!D47<200,3,1)))),"?") -> 5 | G9: 1. Sec2 H250~H252 2. Sec9 자연발화온도(AIT) | H9: 0 | I9: 경미한 주의 흡습발열 가능성 | J9: 흡습발열 H252 또는 AIT 100~200°C | K9: 자기발열 H251 해당 AIT 54~100°C | L9: 자연발화 H250 해당 AIT<54°C | O9: 근거: GHS 자연발화성·자기발열성 분류 ▸ 주요 출처 ① 환경부 고시 제2023-2호 「화학물질의 분류·표시에 관한 규정」 H250(자연발화성), H251(자기발열 대량), H252(자기발열) 코드 정의 ② UN GHS 제9개정판 Part 3.5 자연발화성 액체·고체 분류 기준 (AIT 기준 및 UN 2.1호 시험) ③ 소방청 「위험물안전관리법 시행령」 별표1 자연발화성 물질 정의 ▸ 점수 구간 설정 배경 AIT 구간(100·200·300·400°C)은 GHS 자연발화 시험 온도 기준 및 소방청 위험물 분류 온도 기준을 준용함
B10: 3 | C10: 반응성 | D10: 혼합 위험 반응성 (금기물질·혼합금지 성분) | E10: =IFERROR(IF('① 기초Data'!D52>=5,4,IF('① 기초Data'!D52>=3,3,IF('① 기초Data'!D52>=1,2,1))),"?") -> 1 | G10: 1. Sec10 금기물질 종류수 | H10: 금기물질 없음 자유 혼합 가능 | I10: 1~2종 금기 일반 주의 수준 | J10: 3~4종 금기 특정 물질 혼합시 발열 가능 | K10: 5종 이상 금기 독성가스 또는 격렬 발열 반응 | L10: 즉각 폭발·화재 혼합 즉시 폭발 독성가스 다량 | O10: 근거: KOSHA 화학물질 보관·혼합 위험성 ▸ 주요 출처 ① KOSHA GUIDE W-5-2021 「화학물질 안전보관 및 진열에 관한 기술 지침」 금기물질 분류 및 격리 기준 ② KOSHA GUIDE W-23-2020 「화학물질 반응 위험성 평가 지침」 혼합 반응 위험성 평가 방법론 ③ 화학물질관리법 제14조(환경부) 혼합·혼재 금지 물질 관리 기준 ▸ 점수 구간 설정 배경 금기물질 유형 수(1·2·3·5종)는 SDS Sec10의 실제 기재 패턴과 KOSHA 사례 조사를 기반으로 설정
B11: 4 | C11: 부산물 | D11: 독성 부산물·분해·연소 생성물 | E11: =IFERROR(IF('① 기초Data'!D54="CMR급(다이옥신·HCN 등)",5,IF('① 기초Data'!D54="GHS Cat1~2 독성",4,IF('① 기초Data'!D54="GHS Cat3~4 자극성",3,IF('① 기초Data'!D54="저독성·TLV이하",2,1)))),"?") -> 1 | G11: 1. Sec10 분해생성물 2. Sec5 연소생성물 | H11: 부산물 없음 CO₂·H₂O만 생성 | I11: 저독성 부산물 TLV이하 환기로 관리 | J11: 중등독성 GHS Cat3~4 CO·황산화물 등 | K11: 고독성 부산물 GHS Cat1~2 HCl·포름알데히드 | L11: CMR급 부산물 다이옥신·HCN IARC Group1 수준 | O11: 근거: GHS 급성독성 분류 + KOSHA 부산물 평가 ▸ 주요 출처 ① 고용노동부 고시 제2023-9호 「화학물질의 분류·표시 및 물질안전보건자료에 관한 기준」 GHS 급성독성 Cat.1~5 정의 ② KOSHA GUIDE H-63-2022 「화학물질의 유해성 평가 지침」 분해·연소 생성물 독성 평가 방법 ③ 환경부·고용노동부 공동 고시 GHS 유해화학물질 분류 기준 (Cat.1~5: 치명→유해 구분) ▸ 점수 구간 설정 배경 생성물의 GHS 독성 분류 등급 (Cat.1~2 고독성, Cat.3~4 중등독성) 을 직접 적용함
B12: 5 | C12: 불안정성 | D12: 폭발·급분해 불안정성 (열·충격·마찰·정전기) | E12: =IFERROR(MAX(IF(OR('① 기초Data'!D24="H200",'① 기초Data'!D24="H201",'① 기초Data'!D24="H202",'① 기초Data'!D24="H203",'① 기초Data'!D24="H204",'① 기초Data'!D24="H205"),5, IF(OR('① 기초Data'!D24="H206",'① 기초Data'!D24="H240"),4, IF(OR('① 기초Data'!D24="H207",'① 기초Data'!D24="H241"),3, IF(OR('① 기초Data'!D24="H208",'① 기초Data'!D24="H242"),2,1)))), IF('① 기초Data'!D53<100,4, IF('① 기초Data'!D53<150,3, IF('① 기초Data'!D53<300,2,1)))),"?") -> 4 | G12: 1. Sec2 H200~H252 2. Sec9 분해온도 | H12: 안정한 물질 | I12: 경미한 불안정 H208, H242 또는 분해온도<300°C | J12: 중등 불안정 H207, H241 또는 분해온도<150°C | K12: 불안정 H206, H240 또는 분해온도<100°C | L12: 극도 폭발성 H200~H205 UN 1류 위험물 | O12: 근거: GHS 폭발성 분류 + UN TDG + 소방청 ▸ 주요 출처 ① UN 위험물 운송권고(TDG, 22판) Class 1 폭발성 물질 분류 (1.1~1.6등급, 폭발 에너지 기준) ② 환경부 고시 제2023-2호 H200~H205(폭발성), H240~H242(자기반응성/유기과산화물) 분류 기준 ③ 소방청 「위험물안전관리법」 제5류 자기반응성 물질 분류 열분해 온도 기준 적용 ▸ 점수 구간 설정 배경 H코드(H240~H242)의 유기과산화물 A~F형 분류를 3·4·5점으로 매핑하고, 분해온도(100·150·300°C)를 보조 기준 으로 사용
B13: 6 | C13: 불안정성 | D13: 저장 불안정성 (과산화물·자발중합·변질) | E13: 기초Data 연동 참고값 미제공 항목 (유해성 직접 입력) | G13: 1. Sec7 저장조건 2. Sec10 안정성 | H13: 저장 안정 특별조건 불필요 | I13: 경미한 주의 차광·서늘한 곳 | J13: 특별 저장 냉장 또는 불활성 기체 봉입 권장 | K13: 엄격 저장 냉장+불활성기체 봉입+억제제 | L13: 초엄격 저장 극저온·특수용기 실온 자발반응 | O13: 근거: 위험물안전관리법 + 화학물질관리법 ▸ 주요 출처 ① 소방청 「위험물안전관리법」 저장·취급 기준 (시행규칙 별표4~6) 특수인화물·1석유류 저장 기준 ② 화학물질관리법 제15조(환경부) 유해화학물질 보관·저장 시설 기준 ③ KOSHA GUIDE W-7-2020 「화학물질 저장소 안전관리 지침」 냉장·불활성기체 봉입 필요 기준 ▸ 점수 구간 설정 배경 저장 조건의 엄격도(상온→냉장→ 불활성기체→특수용기)를 SDS Sec7 기재 수준과 법적 요구 기준으로 구분
B14: 7 | C14: 화재 | D14: 인화성 | E14: =IFERROR(MAX(IF(OR('① 기초Data'!D23="H220",'① 기초Data'!D23="H222",'① 기초Data'!D23="H224"),5, IF(OR('① 기초Data'!D23="H221",'① 기초Data'!D23="H223",'① 기초Data'!D23="H225",'① 기초Data'!D23="H228"),4, IF(OR('① 기초Data'!D23="H226"),3, IF('① 기초Data'!D23="H227",2,1)))), IF('① 기초Data'!D45>=93,1,IF('① 기초Data'!D45>=60,2,IF('① 기초Data'!D45>=23,3, IF(AND('① 기초Data'!D45<23,'① 기초Data'!D46>35),4,IF(AND('① 기초Data'!D45<23,'① 기초Data'!D46<=35),5,1)))))),"?") -> 5 | G14: 1. Sec2 H220~H228 2. Sec9 인화점/끓는점 | H14: 비인화성 인화점 없음 또는 ≥93°C | I14: 가연성 액체 H227 인화점 60~93°C 예)경유 | J14: 인화성 H226 인화점 23~60°C 예)크실렌(27°C) | K14: 고인화성 H221,H223,H225,H228 인화점<23°C 끓는점>35°C | L14: 극인화성 H220,H222,H224 인화점<23°C 끓는점≤35°C | O14: 근거: 소방청 위험물안전관리법 + GHS 인화점 분류 ▸ 주요 출처 ① 소방청 「위험물안전관리법 시행령」 별표1 인화성 액체 분류 특수인화물(발화점≤100°C 또는 인화점<-20°C) 제1석유류(인화점<21°C) 제2석유류(21~70°C) 제3석유류(70~200°C) ② 환경부 고시 제2023-2호 GHS 인화성 액체 Cat.1~4 기준 H224(Cat.1): FP<23°C+BP≤35°C H225(Cat.2): FP<23°C H226(Cat.3): 23°C≤FP<60°C H227(Cat.4): 60°C≤FP≤93°C ▸ 점수 구간 설정 배경 GHS Cat.1~4를 1~5점에 매핑하되, 소방청 위험물 분류와 연계하여 23·60·93°C를 경계 기준으로 설정
B15: 8 | C15: 폭발 | D15: 폭발성·산화성 | E15: =IFERROR(MAX(IF(OR('① 기초Data'!D24="H200",'① 기초Data'!D24="H201",'① 기초Data'!D24="H202"),5, IF(OR('① 기초Data'!D24="H203",'① 기초Data'!D24="H204",'① 기초Data'!D24="H205"),4,1)), IF('① 기초Data'!D25="H270",5,IF('① 기초Data'!D25="H271",4,IF('① 기초Data'!D25="H272 Cat2",3,IF('① 기초Data'!D25="H272 Cat3",2,1))))),"?") -> 1 | G15: 1. Sec2 H200~H205, H270~H272 | H15: 해당 없음 H200~H272 없음 | I15: 약한 산화성 H272 Cat3 | J15: 중등 산화성 H272 Cat2 | K15: 강산화성 H271 Cat1 또는 폭발성 1.3~1.4류 | L15: 극강 폭발성 H200~H202 H270 | O15: 근거: GHS 폭발성·산화성 분류 + UN TDG ▸ 주요 출처 ① 환경부 고시 제2023-2호 GHS 폭발성(H200~H205) GHS 산화성 액체·고체(H270~H272) 분류 기준 및 시험 방법 ② UN 위험물 운송권고(TDG, 22판) Class 1(폭발성), Class 5.1(산화성) 국제 운송 분류 기준 ③ 소방청 「위험물안전관리법」 제1류(산화성 고체), 제5류(자기반응성) 국내 위험물 분류 기준 ▸ 점수 구간 설정 배경 GHS 산화성 Cat.1→5점, Cat.2→4점, Cat.3→3점으로 직접 매핑하고, 폭발성 등급(1.1~1.2류)은 최고점 부여
B17: ① 유해성 합계 | E17: =SUM(F8:F15) -> 0 | G17: 유해성 점수 합산, 8개 항목 × 최대5점 = 최대 40점
B18: ② 고위험항목 가중치 (유해성 최고값 5점 : +2 / 4점 : +1점) | E18: =IF(MAX(F8:F15)>=5,2,IF(MAX(F8:F15)>=4,1,0)) -> 0 | G18: 고위험 항목이 다른 항목의 낮은 점수로 인해 합산 시 희석되지 않도록 가중치(1~2점)로 보정
B19: ③ 유해성 최종 점수 (①+②, 최대 40점) | E19: =MIN(40,E17+E18) -> 0 | G19: 최종 유해성 점수 = 유해성합계 + 고위험항목 가중 (최대 40점)
B20: ④ 유해성 등급 (1~5등급) | E20: =IF(E19<8.5,1,IF(E19<16.5,2,IF(E19<24.5,3,IF(E19<33.5,4,5)))) -> 1 | G20: 8점→1등급, 9~16점→2등급, 17~24점→3등급, 25~33점→4등급, 34점 이상→5등급
B22: Ⅱ. 가능성 산정
B23: 1) ①~③ 가능성 평가항목별 해당사항(D열, 노란색 셀)을 입력하세요. (드롭박스 선택) 2) 가능성 평가항목을 모두 입력한 후, 산정된 가능성 등급(28행, 1~5등급)을 확인하세요.
B24: ① 취급 횟수 | E24: =IFERROR(VLOOKUP(D24,'(수정금지) 기준정보'!C212:F217,4,FALSE),"") | G24: 1점: 연 1~2회 | 2점: 연 3~11회 | 3점: 월 1회 이상 | 4점: 주 1회 이상 | 5점: 일 1회 이상 (상시 취급)
B25: ② 1회 취급량 | E25: =IFERROR(VLOOKUP(D25,'(수정금지) 기준정보'!D212:F217,3,FALSE),"") | G25: 1점: < 1 kg(L) | 2점: 1 ~ 10 kg(L) | 3점: 10 ~ 100 kg(L) | 4점: 100 ~ 1,000 kg(L) | 5점: > 1,000 kg(L) 또는 대량 상시 취급
B26: ③ 취급 공정 환경 | E26: =IFERROR(VLOOKUP(D26,'(수정금지) 기준정보'!E212:F217,2,FALSE),"") | G26: 1점: 완전 밀폐·자동화 또는 옥외 개방 | 2점: 부분 밀폐 + 환기 양호 | 3점: 일반 옥내 작업 (기본 환기) | 4점: 밀폐 공간 또는 환기 부족 | 5점: 고온·고압·복합 위험 환경
B27: ④ 가능성 점수 (①+②+③, 최대 15점) | E27: =SUM(E24:E26) -> 0 | G27: 기본 가능성 점수 = ①+②+③ (최대 15점)
B28: ⑤ 가능성 등급 (1~5등급, 저감대책 적용 전) | E28: =IF(E27<3.5,1,IF(E27<6.5,2,IF(E27<9.5,3,IF(E27<12.5,4,5)))) -> 1 | G28: 3점→1등급, 4~6→2등급, 7~9→3등급, 10~12→4등급, 13점 이상→5등급
B30: Ⅲ. 위험성 결정
B31: 1) 위에서 산정된 유해성/가능성에 따라 결정된 위험도를 확인하세요.
B32: 위험도 (유해성등급 × 가능성등급) | E32: =E20*E28 -> 1 | G32: 최대 25점 (5×5) | 저위험 1~3 | 중위험 4~8 | 고위험 9~16 | 허용불가 17~25
B33: 위험 수준 / 허용 여부 | E33: =IF(E32<3.5,"낮음",IF(E32<8.5,"보통",IF(E32<16.5,"높음","매우 높음"))) -> 낮음 | G33: =IF(E32<=8,"✅ 허용 가능","🟠 허용 불가 — 저감대책 적용하여 위험도 감소(8이하) 후 도입 가능 ☞ 하단의 'Ⅳ. 위험성 저감대책 수립' 필수 작성") -> ✅ 허용 가능
B35: Ⅳ. 위험성 저감대책 수립
B36: 1) Ⅲ. 위험성이 허용 불가 수준인 경우, 저감대책을 수립하여 위험도를 8 이하로 낮추어야 도입이 가능하며, 도입/취급 前 수립한 저감대책을 이행하세요. - 저감대책은 공학적→운영적→행정적→보호구 순의 위계로 구분되며, 각 저감대책 적용 시 가능성 등급을 낮춰 위험도를 저감합니다. (유해성은 물질 고유 특성이므로 저감 대상에서 제외) - 저감대책은 '⑥ 저감대책DB' Sheet에서 선택한 후, 적용할 **DB No.**를 입력합니다. (저감대책 DB List는 필요시 사업장에서 '⑥ 저감대책DB' Sheet에 추가하여 운영 가능합니다) 2) Ⅲ. 위험성이 허용 가능 수준인 경우에도, 적용할 저감대책이 있는 경우 이를 입력하여 최종 위험도를 확인하세요.
B38: 1. [참고] 고위험 항목 추천 저감대책
B39: 1) 고위험 항목(유해성/가능성 4,5점)에 적용 가능한 저감대책 추천 - 유해성 및 가능성 평가 결과가 4~5점인 항목에 대해, 해당 항목에 **특화된 저감대책**을 제시합니다. - 본 추천은 참고용이며, 현장 여건에 따라 다른 저감대책을 선택·적용할 수 있습니다. - 항목별 특화 대책 외에도 공통 적용 가능한 저감대책이 DB에 등록되어 있으니, 함께 확인해 주시기 바랍니다.
B40: 구분 | C40: 항목 No. | D40: 평가 항목 | E40: 점수 | F40: 추천 저감대책
F41: 공학적 제어 | H41: 운영적 제어 | J41: 행정적 제어 | L41: 보호구(PPE)
F42: DB No. | G42: 내용 | H42: DB No. | I42: 내용 | J42: DB No. | K42: 내용 | L42: DB No. | M42: 내용
B43: 유해성 | C43: =B8 -> 1 | D43: =D8 -> 물·산·염기와의 접촉 반응성 (발열, 가스 발생 등) | E43: =F8 -> 0 | F43: =IF(E43>=4, "PC-E-03", "—") -> — | G43: =IFERROR(VLOOKUP(F43,'⑥ 저감대책DB'!$B:$H,5,FALSE()),"") | H43: =IF(E43>=4, "PC-O-04", "—") -> — | I43: =IFERROR(VLOOKUP(H43,'⑥ 저감대책DB'!$B:$H,5,FALSE()),"") | J43: =IF(E43>=4, "PC-A-02", "—") -> — | K43: =IFERROR(VLOOKUP(J43,'⑥ 저감대책DB'!$B:$H,5,FALSE()),"") | L43: =IF(E43>=4, "PC-P-02", "—") -> — | M43: =IFERROR(VLOOKUP(L43,'⑥ 저감대책DB'!$B:$H,5,FALSE()),"")
B44: 유해성 | C44: =B9 -> 2 | D44: =D9 -> 공기·수분 반응·자연발화 (흡습 발열, 자기발화) | E44: =F9 -> 0 | F44: =IF(E44>=4, "PC-E-05", "—") -> — | G44: =IFERROR(VLOOKUP(F44,'⑥ 저감대책DB'!$B:$H,5,FALSE()),"") | H44: =IF(E44>=4, "PC-O-03", "—") -> — | I44: =IFERROR(VLOOKUP(H44,'⑥ 저감대책DB'!$B:$H,5,FALSE()),"") | J44: =IF(E44>=4, "PC-A-03", "—") -> — | K44: =IFERROR(VLOOKUP(J44,'⑥ 저감대책DB'!$B:$H,5,FALSE()),"") | L44: =IF(E44>=4, "PC-P-01", "—") -> — | M44: =IFERROR(VLOOKUP(L44,'⑥ 저감대책DB'!$B:$H,5,FALSE()),"")
B45: 유해성 | C45: =B10 -> 3 | D45: =D10 -> 혼합 위험 반응성 (금기물질·혼합금지 성분) | E45: =F10 -> 0 | F45: =IF(E45>=4, "PC-E-10", "—") -> — | G45: =IFERROR(VLOOKUP(F45,'⑥ 저감대책DB'!$B:$H,5,FALSE()),"") | H45: =IF(E45>=4, "PC-O-04", "—") -> — | I45: =IFERROR(VLOOKUP(H45,'⑥ 저감대책DB'!$B:$H,5,FALSE()),"") | J45: =IF(E45>=4, "PC-A-02", "—") -> — | K45: =IFERROR(VLOOKUP(J45,'⑥ 저감대책DB'!$B:$H,5,FALSE()),"") | L45: =IF(E45>=4, "—", "—") -> — | M45: =IFERROR(VLOOKUP(L45,'⑥ 저감대책DB'!$B:$H,5,FALSE()),"")
B46: 유해성 | C46: =B11 -> 4 | D46: =D11 -> 독성 부산물·분해·연소 생성물 | E46: =F11 -> 0 | F46: =IF(E46>=4, "PC-E-11", "—") -> — | G46: =IFERROR(VLOOKUP(F46,'⑥ 저감대책DB'!$B:$H,5,FALSE()),"") | H46: =IF(E46>=4, "—", "—") -> — | I46: =IFERROR(VLOOKUP(H46,'⑥ 저감대책DB'!$B:$H,5,FALSE()),"") | J46: =IF(E46>=4, "PC-A-04", "—") -> — | K46: =IFERROR(VLOOKUP(J46,'⑥ 저감대책DB'!$B:$H,5,FALSE()),"") | L46: =IF(E46>=4, "PC-P-01", "—") -> — | M46: =IFERROR(VLOOKUP(L46,'⑥ 저감대책DB'!$B:$H,5,FALSE()),"")
...

Sheet ③ 환경오염 위험성
A1: 환경오염 위험성
A2: Environmental Pollution Hazard | 환경오염 (수계, 토양, 생물, 대기)
B4: Ⅰ. 유해성 산정
B5: 1) 8개의 유해성 평가항목별 유해성 점수(F열, 노란색 셀)를 입력하세요. - '[참고값] 유해성'(E열)은 '①기초Data'Sheet와 연동되어 유해성(1~5점)을 제시합니다. 해당 값을 참고하여 진행하시고, 만일 [참고값]과 다르게 유해성을 입력하는 경우, '비고'(M열)에 다르게 평가한 사유 기재 要 2) 8개의 유해성 평가항목을 모두 입력한 후, 산정된 유해성 등급(20행, 1~5등급)을 확인하세요.
B6: No. | C6: 구분 | D6: 평가 항목 | E6: [참고값] 유해성 (①기초Data 연동) | F6: ▶유해성 입력 (1~5) | G6: 평가 기준 | M6: 비고
G7: MSDS 확인 항목 | H7: 1점 (미미) | I7: 2점 (경미) | J7: 3점 (보통) | K7: 4점 (중대) | L7: 5점 (치명) | O7: [참고] 유해성 기준 출처 및 배경
B8: 1 | C8: 수계오염 | D8: 수생 생물 급성 독성 | E8: =IFERROR(MAX(IF('① 기초Data'!D38="H400",5, IF('① 기초Data'!D38="H401",4, IF('① 기초Data'!D38="H402",3,1))), IF('① 기초Data'!D62<=1,5, IF('① 기초Data'!D62<=10,4, IF('① 기초Data'!D62<=100,3, IF('① 기초Data'!D62<=1000,2,1)))), IF('① 기초Data'!D63<=1,5, IF('① 기초Data'!D63<=10,4, IF('① 기초Data'!D63<=100,3, IF('① 기초Data'!D63<=1000,2,1))))),"?") -> 5 | G8: 1. Sec2 H400~H402 2. Sec12 어류LC50 3. Sec12 물벼룩/갑각류EC50 | H8: 없음 LC50/EC50 >1000mg/L | I8: 저독성 LC50/EC50 100~1000mg/L | J8: 중등독성 H402 LC50/EC50 10~100mg/L | K8: 고독성 H401 LC50/EC50 1~10mg/L | L8: 극독성 H400 LC50/EC50 ≤1mg/L | O8: 근거: GHS 수생독성 분류 + OECD 시험지침 ▸ 주요 출처 ① 환경부 고시 제2023-2호 「화학물질의 분류·표시에 관한 규정」 수생 급성독성 Cat.1~3 분류 기준 H400(≤1mg/L), H401(1~10), H402(10~100mg/L) ② OECD 시험지침 TG 203(2019) 어류 급성 독성 시험 LC50(96h) 측정 표준 방법 ③ OECD 시험지침 TG 202(2004) 물벼룩 급성 독성 시험 EC50(48h) 측정 표준 방법
B9: 2 | C9: 수계오염 | D9: 수생 생물 만성 독성 | E9: =IFERROR(IF('① 기초Data'!D39="H410",5,IF('① 기초Data'!D39="H411",4,IF('① 기초Data'!D39="H412",3,IF('① 기초Data'!D39="H413",2,1)))),"?") -> 1 | G9: 1. Sec2 H410~H413 | H9: 없음 또는 자료없음 | I9: 저독성 H413 | J9: 중등독성 H412 | K9: 고독성 H411 | L9: 극독성 H410 | O9: 근거: GHS 만성 수생독성 분류 + 화평법 ▸ 주요 출처 ① 환경부 고시 제2023-2호 GHS 만성 수생독성 Cat.1~4 H410(Cat.1)~H413(Cat.4) 정의 NOEC 농도 기준 포함 ② 화학물질 등록 및 평가 등에 관한 법률(화평법, 환경부) 제23조 장기독성 자료 요구 기준 ③ OECD TG 210(2013) 어류 초기 생활사 독성 시험, TG 211(2012) 물벼룩 번식 시험 — NOEC 측정 방법 표준 ▸ 점수 구간 설정 배경 GHS 만성독성 H413(Cat.4)→2점, H410(Cat.1)→5점 역매핑 적용
B10: 3 | C10: 수계오염 | D10: 수계 분해성·생분해도 | E10: =IFERROR(MAX(IF(OR('① 기초Data'!D65="없음",'① 기초Data'!D65=""),1, IF(VALUE('① 기초Data'!D65)>180,5, IF(VALUE('① 기초Data'!D65)>60,4, IF(VALUE('① 기초Data'!D65)>28,3, IF(VALUE('① 기초Data'!D65)>10,2,1))))), IF(OR('① 기초Data'!D66="없음",'① 기초Data'!D66=""),1, IF(VALUE('① 기초Data'!D66)<5,5, IF(VALUE('① 기초Data'!D66)<20,4, IF(VALUE('① 기초Data'!D66)<40,3, IF(VALUE('① 기초Data'!D66)<60,2,1)))))),"?") -> 1 | G10: 1. Sec12 생분해도 2. Sec12 DT50 | H10: 빠른 분해 생분해≥60% 또는 무기물·이온화물질 | I10: 비교적 빠름 생분해 40~60% DT50 10~28일 | J10: 중간 분해 생분해 20~40% DT50 28~60일 | K10: 느린 분해 생분해 5~20% DT50 60~180일 | L10: 거의 안됨 생분해<5% DT50>180일 | O10: 근거: OECD 생분해도 시험 + EU PBT 기준 ▸ 주요 출처 ① OECD 시험지침 TG 301B/F(2023) '쉬운 생분해성(Ready biodegradability)' 기준: 28일 내 60% 이상 분해 ② EU REACH 규정(2006/1907/EC) PBT 잔류성 판단 기준: 해수 DT50>60일 또는 담수 DT50>40일 = 잔류성 물질(P) ③ 환경부 화평법 시행규칙 잔류성 물질 등록 기준 (EU REACH PBT 기준 준용) ▸ 점수 구간 설정 배경 OECD 60% 기준과 PBT 판단 기준 DT50(10·28·60·180일)을 결합하여 5단계 구간 설정
B11: 4 | C11: 토양오염 | D11: 토양 흡착성·이동성 (Koc / logKow) | E11: =IFERROR(MAX(IF(OR('① 기초Data'!D49="없음",'① 기초Data'!D49=""),1, IF(VALUE('① 기초Data'!D49)<2,5, IF(VALUE('① 기초Data'!D49)<2.7,4, IF(VALUE('① 기초Data'!D49)<3.5,3, IF(VALUE('① 기초Data'!D49)<4.5,2,1))))), IF(OR('① 기초Data'!D67="없음",'① 기초Data'!D67=""),1, IF(VALUE('① 기초Data'!D67)<50,5, IF(VALUE('① 기초Data'!D67)<200,4, IF(VALUE('① 기초Data'!D67)<1000,3, IF(VALUE('① 기초Data'!D67)<5000,2,1)))))),"?") -> 1 | G11: 1. Sec9 logKow 2. Sec12 Koc | H11: 이동성 없음 Koc≥5,000 또는 logKow≥4.5(이온화) | I11: 낮은 이동성 Koc 1,000~5,000 logKow 3.5~4.5 | J11: 중간 이동성 Koc 200~1,000 logKow 2.7~3.5 | K11: 높은 이동성 Koc 50~200 logKow 2~2.7 | L11: 매우 높은 이동성 Koc<50 logKow<2 | O11: 근거: Koc-이동성 분류 + 화학물질 위해성 평가 ▸ 주요 출처 ① 환경부 고시 제2021-206호 「화학물질의 위해성 평가 등에 관한 규정」 — 토양 이동성 평가 방법 ② Swann 등(1983) 토양 이동성 분류 (Koc 기준, EPA OCSPP 835.1110) Koc <50: 매우 높은 이동성 Koc 50~500: 보통 이동성 Koc >2,000: 낮은 이동성 ③ KOSHA 화학물질 위해성 평가 가이드 logKow ↔ Koc 환산 공식 활용 ▸ 점수 구간 설정 배경 EPA/환경부 토양 이동성 분류 Koc 구간 (50·200·1,000·10,000)을 직접 적용
B12: 5 | C12: 토양오염 | D12: 토양 잔류성 (반감기 DT50) | E12: =IFERROR(IF(OR('① 기초Data'!D65="없음",'① 기초Data'!D65=""),1, IF(VALUE('① 기초Data'!D65)>365,5, IF(VALUE('① 기초Data'!D65)>180,4, IF(VALUE('① 기초Data'!D65)>120,3, IF(VALUE('① 기초Data'!D65)>60,2,1))))),"?") -> 1 | G12: 1. Sec12 DT50 | H12: 빠른 분해 DT50≤60일 무기물→1점 | I12: 비교적 빠름 DT50 60~120일 | J12: 중간 잔류 DT50 120~180일 PBT 기준 P | K12: 높은 잔류 DT50 180~365일 PBT 기준 vP | L12: 매우 높은 잔류 DT50>365일 | O12: 근거: EU PBT 잔류성 기준 + 화평법 ▸ 주요 출처 ① EU REACH Annex XIII PBT 잔류성(P) 기준: 토양 DT50 >120일 vP(very Persistent) 기준: >120일 ② 환경부 화평법 시행규칙 별표5 잔류성·생물농축성·독성(PBT) 기준 (EU REACH 기준 준용) ③ OECD TG 307(2002) 토양 중 분해성(DT50) 시험 표준 ▸ 점수 구간 설정 배경 PBT 잔류성 판단 기준 DT50=120일과 생태계 위험 수준(10·60·180·365일)을 5단계로 구분
B13: 6 | C13: 생물농축 | D13: 생물농축성 (BCF 또는 logKow) | E13: =IFERROR(MAX(IF('① 기초Data'!D68="vPvB 해당",5, IF('① 기초Data'!D68="PBT기준 3가지 해당",4,1)), IF(OR('① 기초Data'!D64="없음",'① 기초Data'!D64=""),1, IF('① 기초Data'!D64>=5000,5, IF('① 기초Data'!D64>=2000,4, IF('① 기초Data'!D64>=500,3, IF('① 기초Data'!D64>=100,2,1))))), IF(OR('① 기초Data'!D49="없음",'① 기초Data'!D49=""),1, IF('① 기초Data'!D49>=5.2,5, IF('① 기초Data'!D49>=4.7,4, IF('① 기초Data'!D49>=4,3, IF('① 기초Data'!D49>=3.2,2,1)))))),"?") -> 1 | G13: 1. Sec12 PBT/vPvB 2. Sec12 BCF 3. Sec9 logKow | H13: 농축 없음 BCF<100 또는 logKow<3.2 | I13: 낮은 농축 BCF 100~500 logKow 3.2~4.0 | J13: 중간 농축 BCF 500~2,000 logKow 4.0~4.7 | K13: 높은 농축 BCF 2,000~5,000 logKow 4.7~5.2 REACH PBT | L13: 매우 높음 BCF≥5,000 또는 logKow ≥5.2 REACH vPvB 명시 | O13: 근거: EU PBT/BCF 기준 + 화평법 생물농축 ▸ 주요 출처 ① EU REACH Annex XIII 생물농축성(B) 기준: BCF>2,000 vB(very Bioaccumulative): BCF>5,000 ② OECD TG 305(2012) 어류 생물농축 시험(BCF 측정) logKow ↔ BCF 상관관계 활용 ③ 환경부 화평법 시행규칙 생물농축성 등록·평가 기준 (EU REACH Annex XIII 준용) ▸ 점수 구간 설정 배경 EU REACH BCF 기준(2,000/5,000)을 4·5점 경계로 사용하고, 100·500·2,000을 1~3점 경계로 설정
B14: 7 | C14: 생물농축 | D14: PBT/vPvB 복합 특성 | E14: =IFERROR(IF('① 기초Data'!D68="vPvB 해당",5, IF('① 기초Data'!D68="PBT기준 3가지 해당",4, IF('① 기초Data'!D68="PBT 2가지 해당",3, IF('① 기초Data'!D68="PBT 1가지 해당",2,1)))),"?") -> 1 | G14: 1. Sec12 PBT/vPvB | H14: PBT 비해당 3기준 미달 | I14: 1가지 기준 해당 | J14: 2가지 기준 해당 | K14: PBT 해당 3가지 기준 충족 | L14: vPvB 해당 | O14: 근거: 화평법 PBT 기준 + EU REACH ▸ 주요 출처 ① 화학물질 등록 및 평가 등에 관한 법률(화평법) 시행규칙 별표5(환경부) PBT(잔류성·농축성·독성) 및 vPvB(극잔류성·극농축성) 판단 기준 ② EU REACH Annex XIII(2011) PBT/vPvB 물질 평가 기준 — 화평법 PBT 기준의 모태 ③ 환경부 화학물질안전원 「화학물질 위해성 평가 방법 안내」 PBT 스크리닝 절차 안내 ▸ 점수 구간 설정 배경 P·B·T 3개 기준 충족 여부를 충족 개수(0→1→2→3개)로 단계화하고, vPvB는 가장 높은 위험으로 분류
B15: 8 | C15: 대기오염 | D15: 대기오염 영향 (VOC, ODS) | E15: =IFERROR(MAX(IF('① 기초Data'!D40="H420",5, 1), IF(OR('① 기초Data'!D48="없음",'① 기초Data'!D48=""),1, IF(VALUE('① 기초Data'!D48)>=100,4, IF(VALUE('① 기초Data'!D48)>=10,3, IF(VALUE('① 기초Data'!D48)>=1,2, IF(VALUE('① 기초Data'!D48)<1,1,1)))))),"?") -> 1 | G15: 1. Sec2 H420 2. Sec9 증기압 | H15: 영향 없음 비VOC·H420없음 증기압<1mmHg | I15: 낮음 증기압 1~10mmHg VOC 해당 | J15: 중등 증기압 10~100mmHg 광화학스모그 | K15: 높음 증기압≥100mmHg | L15: 심각 H420(ODS) | O15: 근거: 대기환경보전법 + 몬트리올 의정서 ▸ 주요 출처 ① 환경부 대기환경보전법 제44조 VOC 배출 사업장 관리 기준 (증기압·발생량 기반 규제) ② GHS H420 코드 오존층 유해성(Hazardous to the ozone layer) — 몬트리올 의정서 규제 물질 해당 시 부여 ③ 환경부 「오존층 보호를 위한 특정물질의 제조규제 등에 관한 법률(오존층보호법)」 ▸ 점수 구간 설정 배경 H420(ODS) 해당→5점(국제협약 규제) 증기압 기준(1·10·100 mmHg)은 VOC 배출 잠재성과 연관된 KOSHA 노출 가능성 지표 준용
B17: ① 유해성 합계 | E17: =SUM(F8:F15) -> 0 | G17: 유해성 점수 합산, 8개 항목 × 최대5점 = 최대 40점
B18: ② 고위험항목 가중치 (유해성 최고값 5점 : +2 / 4점 : +1점) | E18: =IF(MAX(F8:F15)>=5,2,IF(MAX(F8:F15)>=4,1,0)) -> 0 | G18: 고위험 항목이 다른 항목의 낮은 점수로 인해 합산 시 희석되지 않도록 가중치(1~2점)로 보정
B19: ③ 유해성 최종 점수 (①+②, 최대 40점) | E19: =MIN(40,E17+E18) -> 0 | G19: 최종 유해성 점수 = 유해성합계 + 고위험항목 가중 (최대 40점)
B20: ④ 유해성 등급 (1~5등급) | E20: =IF(E19<8.5,1,IF(E19<16.5,2,IF(E19<24.5,3,IF(E19<33.5,4,5)))) -> 1 | G20: 8점→1등급, 9~16점→2등급, 17~24점→3등급, 25~33점→4등급, 34점 이상→5등급
B22: Ⅱ. 가능성 산정
B23: 1) ①~③ 가능성 평가항목별 해당사항(D열, 노란색 셀)을 입력하세요. (드롭박스 선택) 2) 가능성 평가항목을 모두 입력한 후, 산정된 가능성 등급(28행, 1~5등급)을 확인하세요.
B24: ① 취급 횟수 | E24: =IFERROR(VLOOKUP(D24,'(수정금지) 기준정보'!C220:F225,4,FALSE),"") | G24: 1점: 연 1~2회 | 2점: 연 3~11회 | 3점: 월 1회 이상 | 4점: 주 1회 이상 | 5점: 일 1회 이상 (상시 취급)
B25: ② 1회 취급량 | E25: =IFERROR(VLOOKUP(D25,'(수정금지) 기준정보'!D220:F225,3,FALSE),"") | G25: 1점: < 1 kg(L) | 2점: 1 ~ 10 kg(L) | 3점: 10 ~ 100 kg(L) | 4점: 100 ~ 1,000 kg(L) | 5점: ≥ 1,000 kg(L) 또는 대량 상시 취급
B26: ③ 환경 접촉 가능성 | E26: =IFERROR(VLOOKUP(D26,'(수정금지) 기준정보'!E220:F225,2,FALSE),"") | G26: 1점: 밀폐 공정 | 2점: 사용 후 즉시 밀봉 (유사시 즉시 전량 회수 가능) | 3점: 주기적 사용, 소량 잔류·배출 또는 대기 휘발 가능 (유사시 외부 누출 가능성 有) | 4점: 반복적 사용, 수계·토양 접촉 또는 대기 배출 가능성 상당 | 5점: 개방 공정, 수계·토양·대기 배출 경로 상시 존재
B27: ④ 가능성 점수 (①+②+③, 최대 15점) | E27: =SUM(E24:E26) -> 0 | G27: 기본 가능성 점수 = ①+②+③ (최대 15점)
B28: ⑤ 가능성 등급 (1~5등급, 저감대책 적용 전) | E28: =IF(E27<3.5,1,IF(E27<6.5,2,IF(E27<9.5,3,IF(E27<12.5,4,5)))) -> 1 | G28: 3점→1등급, 4~6→2등급, 7~9→3등급, 10~12→4등급, 13점 이상→5등급
B30: Ⅲ. 위험성 결정
B31: 1) 위에서 산정된 유해성/가능성에 따라 결정된 위험도를 확인하세요.
B32: 위험도 (유해성등급 × 가능성등급) | E32: =E20*E28 -> 1 | G32: 최대 25점 (5×5) | 저위험 1~3 | 중위험 4~8 | 고위험 9~16 | 허용불가 17~25
B33: 위험 수준 / 허용 여부 | E33: =IF(E32<3.5,"낮음",IF(E32<8.5,"보통",IF(E32<16.5,"높음","매우 높음"))) -> 낮음 | G33: =IF(E32<=8,"✅ 허용 가능","🟠 허용 불가 — 저감대책 적용하여 위험도 감소(8이하) 후 도입 가능 ☞ 하단의 'Ⅳ. 위험성 저감대책 수립' 필수 작성") -> ✅ 허용 가능
B35: Ⅳ. 위험성 저감대책 수립
B36: 1) Ⅲ. 위험성이 허용 불가 수준인 경우, 저감대책을 수립하여 위험도를 8 이하로 낮추어야 도입이 가능하며, 도입/취급 前 수립한 저감대책을 이행하세요. - 저감대책은 공학적→운영적→행정적 순의 위계로 구분되며, 각 저감대책 적용 시 가능성 등급을 낮춰 위험도를 저감합니다. (유해성은 물질 고유 특성이므로 저감 대상에서 제외) - 저감대책은 '⑥ 저감대책DB' Sheet에서 선택한 후, 적용할 **DB No.**를 입력합니다. (저감대책 DB List는 필요시 사업장에서 '⑥ 저감대책DB' Sheet에 추가하여 운영 가능합니다) 2) Ⅲ. 위험성이 허용 가능 수준인 경우에도, 적용할 저감대책이 있는 경우 이를 입력하여 최종 위험도를 확인하세요.
B38: 1. [참고] 고위험 항목 추천 저감대책
B39: 1) 고위험 항목(유해성/가능성 4,5점)에 적용 가능한 저감대책 추천 - 유해성 및 가능성 평가 결과가 4~5점인 항목에 대해, 해당 항목에 **특화된 저감대책**을 제시합니다. - 본 추천은 참고용이며, 현장 여건에 따라 다른 저감대책을 선택·적용할 수 있습니다. - 항목별 특화 대책 외에도 공통 적용 가능한 저감대책이 DB에 등록되어 있으니, 함께 확인해 주시기 바랍니다.
B40: 구분 | C40: 항목 No. | D40: 평가 항목 | E40: 점수 | F40: 추천 저감대책
F41: 공학적 제어 | H41: 운영적 제어 | J41: 행정적 제어
F42: DB No. | G42: 내용 | H42: DB No. | I42: 내용 | J42: DB No. | K42: 내용
B43: 유해성 | C43: =B8 -> 1 | D43: =D8 -> 수생 생물 급성 독성 | E43: =F8 -> 0 | F43: =IF(E43>=4, "EN-E-02", "—") -> — | G43: =IFERROR(VLOOKUP(F43,'⑥ 저감대책DB'!$B:$H,5,FALSE()),"") | H43: =IF(E43>=4, "EN-O-03", "—") -> — | I43: =IFERROR(VLOOKUP(H43,'⑥ 저감대책DB'!$B:$H,5,FALSE()),"") | J43: =IF(E43>=4, "EN-A-04", "—") -> — | K43: =IFERROR(VLOOKUP(J43,'⑥ 저감대책DB'!$B:$H,5,FALSE()),"")
B44: 유해성 | C44: =B9 -> 2 | D44: =D9 -> 수생 생물 만성 독성 | E44: =F9 -> 0 | F44: =IF(E44>=4, "EN-E-02", "—") -> — | G44: =IFERROR(VLOOKUP(F44,'⑥ 저감대책DB'!$B:$H,5,FALSE()),"") | H44: =IF(E44>=4, "EN-O-02", "—") -> — | I44: =IFERROR(VLOOKUP(H44,'⑥ 저감대책DB'!$B:$H,5,FALSE()),"") | J44: =IF(E44>=4, "EN-A-05", "—") -> — | K44: =IFERROR(VLOOKUP(J44,'⑥ 저감대책DB'!$B:$H,5,FALSE()),"")
B45: 유해성 | C45: =B10 -> 3 | D45: =D10 -> 수계 분해성·생분해도 | E45: =F10 -> 0 | F45: =IF(E45>=4, "EN-E-08", "—") -> — | G45: =IFERROR(VLOOKUP(F45,'⑥ 저감대책DB'!$B:$H,5,FALSE()),"") | H45: =IF(E45>=4, "EN-O-01", "—") -> — | I45: =IFERROR(VLOOKUP(H45,'⑥ 저감대책DB'!$B:$H,5,FALSE()),"") | J45: =IF(E45>=4, "EN-A-05", "—") -> — | K45: =IFERROR(VLOOKUP(J45,'⑥ 저감대책DB'!$B:$H,5,FALSE()),"")
B46: 유해성 | C46: =B11 -> 4 | D46: =D11 -> 토양 흡착성·이동성 (Koc / logKow) | E46: =F11 -> 0 | F46: =IF(E46>=4, "EN-E-05", "—") -> — | G46: =IFERROR(VLOOKUP(F46,'⑥ 저감대책DB'!$B:$H,5,FALSE()),"") | H46: =IF(E46>=4, "EN-O-03", "—") -> — | I46: =IFERROR(VLOOKUP(H46,'⑥ 저감대책DB'!$B:$H,5,FALSE()),"") | J46: =IF(E46>=4, "EN-A-03", "—") -> — | K46: =IFERROR(VLOOKUP(J46,'⑥ 저감대책DB'!$B:$H,5,FALSE()),"")
...

Sheet ④ 작업자 안전보건
A1: 작업자 안전보건 위험성
A2: Worker Safety & Health Hazard | 급성독성·만성독성·노출기준
B4: Ⅰ. 유해성 산정
B5: 1) 8개의 유해성 평가항목별 유해성 점수(F열, 노란색 셀)를 입력하세요. - '[참고값] 유해성'(E열)은 '①기초Data'Sheet와 연동되어 유해성(1~5점)을 제시합니다. 해당 값을 참고하여 진행하시고, 만일 [참고값]과 다르게 유해성을 입력하는 경우, '비고'(M열)에 다르게 평가한 사유 기재 要 2) 8개의 유해성 평가항목을 모두 입력한 후, 산정된 유해성 등급(20행, 1~5등급)을 확인하세요.
B6: No. | C6: 구분 | D6: 평가 항목 | E6: [참고값] 유해성 (①기초Data 연동) | F6: ▶유해성 입력 (1~5) | G6: 평가 기준 | M6: 비고
G7: MSDS 확인 항목 | H7: 1점 (미미) | I7: 2점 (경미) | J7: 3점 (보통) | K7: 4점 (중대) | L7: 5점 (치명) | O7: [참고] 유해성 기준 출처 및 배경
B8: 1 | C8: 급성독성 | D8: 흡입 독성 (증기, 분기/미스트) | E8: =IFERROR(MAX(IF('① 기초Data'!D29="H330",5, IF('① 기초Data'!D29="H331",4, IF('① 기초Data'!D29="H332",3, IF('① 기초Data'!D29="H333",3,1)))), IF('① 기초Data'!D56<=0.5,5, IF('① 기초Data'!D56<=2,4, IF('① 기초Data'!D56<=20,3, IF('① 기초Data'!D56<=50,2,1)))), IF('① 기초Data'!D57<=0.5,5, IF('① 기초Data'!D57<=1,4, IF('① 기초Data'!D57<=5,3, IF('① 기초Data'!D57<=12.5,2,1))))),"?") -> 5 | G8: 1. Sec2 H330~H333 2. Sec11 흡입LC50 (mg/L) | H8: 독성 없음 LC50(증기)>50mg/L LC50(분진/미스트)>12.5mg/L | I8: 저독성 H333 LC50(증기) 20~50mg/L LC50(분진/미스트) 5.0~12.5mg/L | J8: 중등독성 H332 LC50(증기) 2.0~20mg/L LC50(분진/미스트) 1.0~5.0mg/L | K8: 고독성 H331 LC50(증기) 0.5~2.0mg/L LC50(분진/미스트) 0.5~1.0mg/L | L8: 극독성 H330 LC50(증기)≤0.5mg/L LC50(분진/미스트)≤0.5mg/L | O8: 근거: GHS 흡입독성 + 고용부 노출기준 고시 ▸ 주요 출처 ① 고용노동부 고시 제2023-43호 「화학물질 및 물리적 인자의 노출기준」 — TLV-TWA 수치 목록 ② 환경부·고용노동부 공동 고시 GHS 급성독성 흡입 분류 기준 H330(Cat.1~2): LC50≤0.5 mg/L H331(Cat.3): 0.5~1.0 mg/L H332(Cat.4): 1~5 mg/L ③ KOSHA GUIDE H-44-2022 「작업환경측정 및 정도관리 지침」 TWA 기반 노출 수준 평가 방법 ▸ 점수 구간 설정 배경 LC50 구간(<0.5/0.5~1/1~5/5~20/>20 mg/L)은 GHS 급성독성 Cat.1~5를 직접 적용하고, TWA와 MAX 사용
B9: 2 | C9: 급성독성 | D9: 경구·경피 독성 | E9: =IFERROR(MAX(IF(OR('① 기초Data'!D30="H300",'① 기초Data'!D30="H310"),5, IF(OR('① 기초Data'!D30="H301",'① 기초Data'!D30="H304",'① 기초Data'!D30="H311"),4, IF('① 기초Data'!D30="H305",3, IF(OR('① 기초Data'!D30="H302",'① 기초Data'!D30="H312"),2, 1)))), IF('① 기초Data'!D58<=50,5, IF('① 기초Data'!D58<=300,4, IF('① 기초Data'!D58<=1000,3, IF('① 기초Data'!D58<=2000,2,1)))), IF('① 기초Data'!D59<=200,5, IF('① 기초Data'!D59<=1000,4, IF('① 기초Data'!D59<=1500,3, IF('① 기초Data'!D59<=2000,2,1))))),"?") -> 5 | G9: 1. Sec2 H300~302, H304~305, H310~312 2. Sec11 경구/경피LD50 (mg/kg) | H9: 독성 없음 경구LD50 >2,000mg/kg 경피LD50 >2000mg/kg | I9: 저독성 H302, H312 경구LD50≤2000mg/kg 경피LD50≤2000mg/kg | J9: 중등독성 H305 경구LD50≤1000mg/kg 경피LD50≤1500mg/kg | K9: 고독성 H301, H304, H311 경구LD50≤300mg/kg 경피LD50≤1000mg/kg | L9: 극독성 H300, H310 경구LD50≤50mg/kg 경피LD50≤200mg/kg | O9: 근거: GHS 경구독성 분류 + LD50 기준 ▸ 주요 출처 ① 환경부·고용노동부 공동 고시 GHS 급성독성 경구 분류 기준 H300(Cat.1~2): LD50≤50 mg/kg H301(Cat.3): 50~300 mg/kg H302(Cat.4): 300~2,000 mg/kg 비분류(Cat.5): >2,000 mg/kg ② UN GHS 제9개정판 Part 3.1 경구·경피·흡입 독성 분류표 (전 세계 동일 기준 적용) ③ OECD TG 401(폐기)/TG 420/425 경구 급성독성 시험 표준 방법 ▸ 점수 구간 설정 배경 GHS LD50 경계값(<5/5~50/50~300 /300~2,000/>2,000 mg/kg)을 5~1점에 직접 매핑
B10: 3 | C10: 급성독성 | D10: 피부·눈 자극성 및 부식성 | E10: =IFERROR(MAX(IF('① 기초Data'!D31="H314 Cat1A",5, IF(OR('① 기초Data'!D31="H314 Cat1B",'① 기초Data'!D31="H314 Cat1"),4, IF(OR('① 기초Data'!D31="H315",'① 기초Data'!D31="H317"),3, IF('① 기초Data'!D31="H316",2, 1)))), IF('① 기초Data'!D32="H318",4, IF('① 기초Data'!D32="H319",3, IF('① 기초Data'!D32="H320",2, 1)))), "?") -> 1 | G10: 1. Sec2 피부 H코드 H314~H317 2. Sec2 눈 H코드 H318~H320 | H10: 자극 없음 H314~H320 없음 | I10: 경미한 자극 H316 또는 H320 | J10: 자극성 H315, H17 또는 H319 | K10: 부식성·손상 H314 Cat1/1B 또는 H318 | L10: 심각한 부식 H314 Cat1A | O10: 근거: GHS 피부·눈 분류 + 산업안전보건기준 ▸ 주요 출처 ① 환경부·고용노동부 공동 고시 GHS 피부 부식성·자극성 분류 H314 Cat.1A: pH≤2 또는 ≥11.5 (피부 파괴 시간 3분 이내) H314 Cat.1: 1~4시간 내 부식 H315 Cat.2: 가역적 자극 ② 고용노동부 고시 제2023-9호 「MSDS 작성에 관한 기준」 H318 눈 심한 손상 Cat.1 기준 ③ OECD TG 404(2015) 피부 자극 TG 405(2012) 눈 자극 시험 ▸ 점수 구간 설정 배경 GHS 부식성·자극성 H코드 체계를 그대로 적용(H314A→5점, H314→4점, H315/H319→3점 등)
B11: 4 | C11: 만성독성 | D11: 발암성 | E11: =IFERROR(MAX(IF('① 기초Data'!D33="H350 Cat1A",5, IF('① 기초Data'!D33="H350 Cat1B",4, IF('① 기초Data'!D33="H351",3, 1))), IF('① 기초Data'!D60="IARC Group1",5, IF('① 기초Data'!D60="IARC Group2A",4, IF('① 기초Data'!D60="IARC Group2B",3, IF('① 기초Data'!D60="IARC Group3",2, 1))))), "?") -> 1 | G11: 1. Sec2 H350~351 2. Sec11 IARC Group | H11: 비발암성 | I11: 불명확 IARC Gr.3 | J11: 발암 의심 H351 IARC Gr.2B | K11: 발암 가능 H350 Cat1B IARC Gr.2A | L11: 확정 발암 H350 Cat1A IARC Gr.1 | O11: 근거: IARC 발암성 분류 + 고용부 특별관리물질 ▸ 주요 출처 ① WHO 국제암연구소(IARC) 발암성 분류 체계 (Monographs) Group 1: 인체 발암성 확인 Group 2A: 발암 가능성 높음 Group 2B: 발암 가능성 있음 Group 3: 분류 불가 ② 고용노동부 고시 제2023-9호 산업안전보건법 시행규칙 별표 특별관리물질 목록 (IARC Group 1 이상 수준) ③ GHS H350(Cat.1A/1B)·H351(Cat.2) 발암성 분류 기준 ▸ 점수 구간 설정 배경 IARC Group 1/2A/2B/3/4를 GHS H350(Cat.1A/1B)·H351(Cat.2)과 교차 검증하여 5단계로 매핑
B12: 5 | C12: 만성독성 | D12: 생식·발달독성 | E12: =IFERROR( IF('① 기초Data'!D34="H360 Cat1A",5, IF('① 기초Data'!D34="H360 Cat1B",4, IF('① 기초Data'!D34="H361",3, IF('① 기초Data'!D34="H362",2, 1)))), "?") -> 1 | G12: 1. Sec2 H360~H362 | H12: 없음 | I12: 불명확 H362 | J12: 의심 H361 | K12: 가능성 높음 H360 Cat1B | L12: 확정 H360 Cat1A | O12: 근거: GHS 생식독성 분류 + 산업안전보건법 ▸ 주요 출처 ① 환경부·고용노동부 공동 고시 GHS 생식독성 분류 기준 H360 Cat.1A: 생식독성 확인 H360 Cat.1B: 생식독성 추정 H361 Cat.2: 생식독성 의심 ② 고용노동부 고시 제2023-9호 산업안전보건법 제125조 CMR 물질 여성 근로자 보호 기준 ③ OECD TG 414(2018) 출생전 발달독성 시험 표준 ▸ 점수 구간 설정 배경 GHS 생식독성 H코드 Cat.1A/1B/2와 '자료없음' 상태를 각각 5/4/3/2점으로 매핑
B13: 6 | C13: 만성독성 | D13: 특정 장기 반복독성 및 호흡기 과민성 | E13: =IFERROR(MAX(IF('① 기초Data'!D35="H370",5, IF('① 기초Data'!D35="H371",4, IF('① 기초Data'!D35="H372",3, IF('① 기초Data'!D35="H373",2, 1)))), IF('① 기초Data'!D36="334",4, IF('① 기초Data'!D36="335",3, IF('① 기초Data'!D36="336",2, 1)))), "?") -> 1 | G13: 1. Sec2 H370~373 2. Sec2 H334~336 | H13: 없음 | I13: 낮음 H373 또는 H336 | J13: 중등 H372 또는 H335 | K13: 높음 H371 또는 H334 | L13: 심각 H370 | O13: 근거: GHS STOT 분류 + KOSHA 직업병 기준 ▸ 주요 출처 ① 환경부·고용노동부 공동 고시 GHS 특정표적장기독성(STOT) 반복노출 분류 기준 H372 Cat.1: 반복노출 장기 손상 H373 Cat.2: 반복노출 손상 우려 ② GHS H334 호흡기 과민성 기준 (흡입 시 알레르기·천식 유발) 직업성 천식 물질 판단 기준 ③ KOSHA GUIDE H-44-2022 직업성 호흡기 질환 예방 지침 LOAEC 기반 STOT 위험 평가 ▸ 점수 구간 설정 배경 GHS H372/H373 코드를 기본 판단에 사용하나, LOAEC 수치(SDS Sec11)를 확인하여 인간이 최종 보정 필요
B14: 7 | C14: 만성독성 | D14: 생식세포 변이원성 | E14: =IFERROR(IF('① 기초Data'!D37="H340 Cat1A",5, IF('① 기초Data'!D37="H340 Cat1B",4, IF('① 기초Data'!D37="H341",3, 1))), "?") -> 1 | G14: 1. Sec2 340~341 | H14: 없음 | I14: - | J14: 의심 H341 | K14: 가능성 높음 H340 Cat1B | L14: 확정 H340 Cat1A | O14: 근거: GHS 변이원성 분류 + 고용부 CMR 기준 ▸ 주요 출처 ① 환경부·고용노동부 공동 고시 GHS 생식세포 변이원성 분류 H340 Cat.1A: DNA 손상 확인 H340 Cat.1B: DNA 손상 추정 H341 Cat.2: DNA 손상 의심 ② OECD 시험지침 TG 471(세균 역돌연변이, Ames) TG 476(in vitro 염색체이상 시험) TG 474(in vivo 소핵 시험) ③ 산업안전보건법 시행규칙 별표 CMR(발암·변이원·생식독성) 물질 특별관리 대상 기준 ▸ 점수 구간 설정 배경 GHS 변이원성 Cat.1A/1B/Cat.2를 5/4/3점, 자료없음→2점, 음성→1점으로 매핑. 변이원성은 발암 전구 과정으로 발암성과 연계하여 중요도 평가
B15: 8 | C15: 노출기준 | D15: 작업환경 노출기준 | E15: =IFERROR(MAX(IF('① 기초Data'!D42<0.1,5, IF('① 기초Data'!D42<1,4, IF('① 기초Data'!D42<10,3, IF('① 기초Data'!D42<100,2,1)))), IF('① 기초Data'!D43<0.05,5, IF('① 기초Data'!D43<0.5,4, IF('① 기초Data'!D43<5,3, IF('① 기초Data'!D43<50,2,1))))),"?") -> 5 | G15: 1. Sec8 TWA mg/m³ 2. Sec8 TWA ppm | H15: 낮은 위험 TWA≥100mg/m³ ≥50ppm | I15: 보통 TWA 10~100mg/m³ 5~50ppm | J15: 중등 TWA 1~10mg/m³ 0.5~5ppm | K15: 고위험 TWA 0.1~1mg/m³ 0.05~0.5ppm | L15: 극고위험 TWA<0.1mg/m³ <0.05ppm | O15: 근거: 고용노동부 노출기준 고시 (가장 중요) ▸ 주요 출처 ① 고용노동부 고시 제2023-43호 「화학물질 및 물리적 인자의 노출기준」 (산업안전보건법 제125조) — 국내 법적 노출기준의 근거 ② ACGIH TLV-TWA (미국 산업위생전문가협의회) 한국 노출기준 설정의 참고 기준 ③ KOSHA GUIDE H-44-2022 「작업환경측정 및 정도관리」 ▸ TWA 점수 구간 설정 배경 고용노동부 고시의 실제 물질별 TWA를 분포 분석하여 5구간으로 설정: • >100 mg/m³(1점): 저독성 용매류 (아세톤 1,200, 에탄올 1,900 mg/m³) • 10~100 mg/m³(2점): 중등독성 (톨루엔 188, 크실렌 434 mg/m³) • 1~10 mg/m³(3점): 고독성 (벤젠 3.2, 포름알데히드 0.37 mg/m³) • 0.1~1 mg/m³(4점): 극고독성 (황산 0.2, 염소 1.5 mg/m³) • <0.1 mg/m³(5점): CMR 특별관리 (6가크롬 0.01, 카드뮴 0.02 mg/m³) → 산업안전보건법 특별관리물질은 대부분 5점 구간에 해당
B17: ① 유해성 합계 | E17: =SUM(F8:F15) -> 0 | G17: 유해성 점수 합산, 8개 항목 × 최대5점 = 최대 40점
B18: ② 고위험항목 가중치 (유해성 최고값 5점 : +2 / 4점 : +1점) | E18: =IF(MAX(F8:F15)>=5,2,IF(MAX(F8:F15)>=4,1,0)) -> 0 | G18: 고위험 항목이 다른 항목의 낮은 점수로 인해 합산 시 희석되지 않도록 가중치(1~2점)로 보정
B19: ③ 유해성 최종 점수 (①+②, 최대 40점) | E19: =MIN(40,E17+E18) -> 0 | G19: 최종 유해성 점수 = 유해성합계 + 고위험항목 가중 (최대 40점)
B20: ④ 유해성 등급 (1~5등급) | E20: =IF(E19<8.5,1,IF(E19<16.5,2,IF(E19<24.5,3,IF(E19<33.5,4,5)))) -> 1 | G20: 8점→1등급, 9~16점→2등급, 17~24점→3등급, 25~33점→4등급, 34점 이상→5등급
B22: Ⅱ. 가능성 산정
B23: 1) ①~③ 가능성 평가항목별 해당사항(D열, 노란색 셀)을 입력하세요. (드롭박스 선택) 2) 가능성 평가항목을 모두 입력한 후, 산정된 가능성 등급(28행, 1~5등급)을 확인하세요.
B24: ① 취급 횟수 | E24: =IFERROR(VLOOKUP(D24,'(수정금지) 기준정보'!C228:F233,4,FALSE),"") | G24: 1점: 연 1~2회 | 2점: 연 3~11회 | 3점: 월 1회 이상 | 4점: 주 1회 이상 | 5점: 일 1회 이상 (상시 취급)
B25: ② 1회 취급량 | E25: =IFERROR(VLOOKUP(D25,'(수정금지) 기준정보'!D228:F233,3,FALSE),"") | G25: 1점: < 1 kg(L) | 2점: 1 ~ 10 kg(L) | 3점: 10 ~ 100 kg(L) | 4점: 100 ~ 1,000 kg(L) | 5점: > 1,000 kg(L) 또는 대량 상시 취급
B26: ③ 취급 공정 환경 | E26: =IFERROR(VLOOKUP(D26,'(수정금지) 기준정보'!E228:F233,2,FALSE),"") | G26: 1점: 완전 자동화·밀폐 | 2점: 밀폐 공간에서 간헐적 취급 | 3점: 부분 개방 환경에서 주기적 취급 | 4점: 개방 환경에서 반복적 취급 | 5점: 개방 공정 1일 노출 4시간 이상
B27: ④ 가능성 점수 (①+②+③, 최대 15점) | E27: =SUM(E24:E26) -> 0 | G27: 기본 가능성 점수 = ①+②+③ (최대 15점)
B28: ⑤ 가능성 등급 (1~5등급, 저감대책 적용 전) | E28: =IF(E27<3.5,1,IF(E27<6.5,2,IF(E27<9.5,3,IF(E27<12.5,4,5)))) -> 1 | G28: 3점→1등급, 4~6→2등급, 7~9→3등급, 10~12→4등급, 13점 이상→5등급
B30: Ⅲ. 위험성 결정
B31: 1) 위에서 산정된 유해성/가능성에 따라 결정된 위험도를 확인하세요.
B32: 위험도 (유해성등급 × 가능성등급) | E32: =E20*E28 -> 1 | G32: 최대 25점 (5×5) | 저위험 1~3 | 중위험 4~8 | 고위험 9~16 | 허용불가 17~25
B33: 위험 수준 / 허용 여부 | E33: =IF(E32<3.5,"낮음",IF(E32<8.5,"보통",IF(E32<16.5,"높음","매우 높음"))) -> 낮음 | G33: =IF(E32<=8,"✅ 허용 가능","🟠 허용 불가 — 저감대책 적용하여 위험도 감소(8이하) 후 도입 가능 ☞ 하단의 'Ⅳ. 위험성 저감대책 수립' 필수 작성") -> ✅ 허용 가능
B35: Ⅳ. 위험성 저감대책 수립
B36: 1) Ⅲ. 위험성이 허용 불가 수준인 경우, 저감대책을 수립하여 위험도를 8 이하로 낮추어야 도입이 가능하며, 도입/취급 前 수립한 저감대책을 이행하세요. - 저감대책은 공학적→운영적→행정적→보호구 순의 위계로 구분되며, 각 저감대책 적용 시 가능성 등급을 낮춰 위험도를 저감합니다. (유해성은 물질 고유 특성이므로 저감 대상에서 제외) - 저감대책은 '⑥ 저감대책DB' Sheet에서 선택한 후, 적용할 **DB No.**를 입력합니다. (저감대책 DB List는 필요시 사업장에서 '⑥ 저감대책DB' Sheet에 추가하여 운영 가능합니다) 2) Ⅲ. 위험성이 허용 가능 수준인 경우에도, 적용할 저감대책이 있는 경우 이를 입력하여 최종 위험도를 확인하세요.
B38: 1. [참고] 고위험 항목 추천 저감대책
B39: 1) 고위험 항목(유해성/가능성 4,5점)에 적용 가능한 저감대책 추천 - 유해성 및 가능성 평가 결과가 4~5점인 항목에 대해, 해당 항목에 **특화된 저감대책**을 제시합니다. - 본 추천은 참고용이며, 현장 여건에 따라 다른 저감대책을 선택·적용할 수 있습니다. - 항목별 특화 대책 외에도 공통 적용 가능한 저감대책이 DB에 등록되어 있으니, 함께 확인해 주시기 바랍니다.
B40: 구분 | C40: 항목 No. | D40: 평가 항목 | E40: 점수 | F40: 추천 저감대책
F41: 공학적 제어 | H41: 운영적 제어 | J41: 행정적 제어 | L41: 보호구(PPE)
F42: DB No. | G42: 내용 | H42: DB No. | I42: 내용 | J42: DB No. | K42: 내용 | L42: DB No. | M42: 내용
B43: 유해성 | C43: =B8 -> 1 | D43: =D8 -> 흡입 독성 (증기, 분기/미스트) | E43: =F8 -> 0 | F43: =IF(E43>=4, "OH-E-03", "—") -> — | G43: =IFERROR(VLOOKUP(F43,'⑥ 저감대책DB'!$B:$H,5,FALSE()),"") | H43: =IF(E43>=4, "OH-O-01", "—") -> — | I43: =IFERROR(VLOOKUP(H43,'⑥ 저감대책DB'!$B:$H,5,FALSE()),"") | J43: =IF(E43>=4, "OH-A-06", "—") -> — | K43: =IFERROR(VLOOKUP(J43,'⑥ 저감대책DB'!$B:$H,5,FALSE()),"") | L43: =IF(E43>=4, "OH-P-01", "—") -> — | M43: =IFERROR(VLOOKUP(L43,'⑥ 저감대책DB'!$B:$H,5,FALSE()),"")
B44: 유해성 | C44: =B9 -> 2 | D44: =D9 -> 경구·경피 독성 | E44: =F9 -> 0 | F44: =IF(E44>=4, "OH-E-05", "—") -> — | G44: =IFERROR(VLOOKUP(F44,'⑥ 저감대책DB'!$B:$H,5,FALSE()),"") | H44: =IF(E44>=4, "OH-O-04", "—") -> — | I44: =IFERROR(VLOOKUP(H44,'⑥ 저감대책DB'!$B:$H,5,FALSE()),"") | J44: =IF(E44>=4, "OH-A-02", "—") -> — | K44: =IFERROR(VLOOKUP(J44,'⑥ 저감대책DB'!$B:$H,5,FALSE()),"") | L44: =IF(E44>=4, "OH-P-02", "—") -> — | M44: =IFERROR(VLOOKUP(L44,'⑥ 저감대책DB'!$B:$H,5,FALSE()),"")
B45: 유해성 | C45: =B10 -> 3 | D45: =D10 -> 피부·눈 자극성 및 부식성 | E45: =F10 -> 0 | F45: =IF(E45>=4, "OH-E-07", "—") -> — | G45: =IFERROR(VLOOKUP(F45,'⑥ 저감대책DB'!$B:$H,5,FALSE()),"") | H45: =IF(E45>=4, "OH-O-06", "—") -> — | I45: =IFERROR(VLOOKUP(H45,'⑥ 저감대책DB'!$B:$H,5,FALSE()),"") | J45: =IF(E45>=4, "OH-A-05", "—") -> — | K45: =IFERROR(VLOOKUP(J45,'⑥ 저감대책DB'!$B:$H,5,FALSE()),"") | L45: =IF(E45>=4, "OH-P-02", "—") -> — | M45: =IFERROR(VLOOKUP(L45,'⑥ 저감대책DB'!$B:$H,5,FALSE()),"")
B46: 유해성 | C46: =B11 -> 4 | D46: =D11 -> 발암성 | E46: =F11 -> 0 | F46: =IF(E46>=4, "OH-E-09", "—") -> — | G46: =IFERROR(VLOOKUP(F46,'⑥ 저감대책DB'!$B:$H,5,FALSE()),"") | H46: =IF(E46>=4, "OH-O-03", "—") -> — | I46: =IFERROR(VLOOKUP(H46,'⑥ 저감대책DB'!$B:$H,5,FALSE()),"") | J46: =IF(E46>=4, "OH-A-03", "—") -> — | K46: =IFERROR(VLOOKUP(J46,'⑥ 저감대책DB'!$B:$H,5,FALSE()),"") | L46: =IF(E46>=4, "OH-P-01", "—") -> — | M46: =IFERROR(VLOOKUP(L46,'⑥ 저감대책DB'!$B:$H,5,FALSE()),"")
...

Sheet ⑤ 종합결과
B1: 화학물질 위험성평가 - 종합결과
B3: 평가유형 | F3: 평가일자
B4: 평가부서 | F4: 평가자
B6: ▶ 평가 대상 화학물질 기본 정보
B7: ='① 기초Data'!B5 -> 제품명 | D7: ='① 기초Data'!C5 -> 0 | F7: ='① 기초Data'!B6 -> 제조사 | H7: ='① 기초Data'!C6 -> 0
B8: 주요 물질명 | D8: ='① 기초Data'!C9 -> 0 | F8: 주요 물질 CAS No. | H8: ='① 기초Data'!D9 -> 0
B9: ='① 기초Data'!B14 -> 취급부서 / 공정 | D9: ='① 기초Data'!C14 -> 0 | F9: ='① 기초Data'!B15 -> 저장·보관(예정) 장소 | H9: ='① 기초Data'!C15 -> 0
B11: ▶ 위험성평가 결과 요약
B12: 분야 | D12: 유해성 등급 | E12: 가능성 등급 (대책 적용 전) | F12: 가능성 등급 (대책 적용 후) | G12: 위험수준 /위험도 | H12: 치명 항목 수 (유해성 5점) | I12: 비고
B13: 물리화학 | D13: ='② 물리화학적 위험성'!E20 -> 1 | E13: ='② 물리화학적 위험성'!E28 -> 1 | F13: ='② 물리화학적 위험성'!E67 -> 1 | G13: ='② 물리화학적 위험성'!E70&" / "&'② 물리화학적 위험성'!E69 -> 저 / 1 | H13: =IF(COUNTIF('② 물리화학적 위험성'!F8:F15,">=5")>=1,COUNTIF('② 물리화학적 위험성'!F8:F15,">=5"),"")
B14: 환경오염 | D14: ='③ 환경오염 위험성'!E20 -> 1 | E14: ='③ 환경오염 위험성'!E28 -> 1 | F14: ='③ 환경오염 위험성'!E66 -> 1 | G14: ='③ 환경오염 위험성'!E69&" / "&'③ 환경오염 위험성'!E68 -> 저 / 1 | H14: =IF(COUNTIF('③ 환경오염 위험성'!F8:F15,">=5")>=1,COUNTIF('③ 환경오염 위험성'!F8:F15,">=5"),"")
B15: 작업자 안전보건 | D15: ='④ 작업자 안전보건'!E20 -> 1 | E15: ='④ 작업자 안전보건'!E28 -> 1 | F15: ='④ 작업자 안전보건'!E67 -> 1 | G15: ='④ 작업자 안전보건'!E70&" / "&'④ 작업자 안전보건'!E69 -> 저 / 1 | H15: =IF(COUNTIF('④ 작업자 안전보건'!F8:F15,">=5")>=1,COUNTIF('④ 작업자 안전보건'!F8:F15,">=5"),"")
B16: 검토 결과 | D16: =IF(MAX('② 물리화학적 위험성'!E69,'③ 환경오염 위험성'!E68,'④ 작업자 안전보건'!E69)>=17,"🔴 허용 불가 — 원칙적 도입/취급 불가 (도입하려면 경영진 예외 승인 필수)",IF(MAX('② 물리화학적 위험성'!E69,'③ 환경오염 위험성'!E68,'④ 작업자 안전보건'!E69)>=10,"🟠 고위험 — 저감대책 보강 후 재평가하여 위험도 감소 후 도입/취급 가능",IF(MAX('② 물리화학적 위험성'!E69,'③ 환경오염 위험성'!E68,'④ 작업자 안전보건'!E69)>=5,"🟡 중위험 — 부서장 승인 후 도입/취급 가능 (추가 저감대책 검토 권장, 모니터링 지속)"&" "&IF(SUM(H13:H15)>=1,"🟠 치명항목(유해성 5점) 有 — SHE부서 검토자 반영 필요",""),"🟢 저위험 — 부서장 승인 후 도입/취급 가능"&" "&IF(SUM(H13:H15)>=1,"🟠 치명항목(유해성 5점) 有 — SHE부서 검토자 반영 필요","")))) -> 🟢 저위험 — 부서장 승인 후 도입/취급 가능
B17: ▶ 적용 기준 — 1-3점: 도입 가능 | 4-8점: 도입 가능(추가 저감대책 검토 권장) | 9-16점: 허용 불가 | 17-25점: 허용 불가 치명항목(유해성 5점) 항목 1개 이상 있는 경우, 위험도 무관 SHE부서 검토자로 반영하여 결재 진행
B19: ▶ 적용 저감대책 및 이행계획
B20: 분야 | C20: 위계 | D20: 저감대책 | G20: 담당자 | H20: 이행 상태 | I20: 완료예정일 | J20: 비고
B21: 물리화학 | C21: 공학 | D21: ='② 물리화학적 위험성'!F59
D22: ='② 물리화학적 위험성'!H59
D23: ='② 물리화학적 위험성'!J59
C24: 운영 | D24: ='② 물리화학적 위험성'!F60
D25: ='② 물리화학적 위험성'!H60
D26: ='② 물리화학적 위험성'!J60
C27: 행정 | D27: ='② 물리화학적 위험성'!F61
D28: ='② 물리화학적 위험성'!H61
D29: ='② 물리화학적 위험성'!J61
C30: 보호구 | D30: ='② 물리화학적 위험성'!F62
D31: ='② 물리화학적 위험성'!H62
D32: ='② 물리화학적 위험성'!J62
B33: 환경오염 | C33: 공학 | D33: ='③ 환경오염 위험성'!F59
D34: ='③ 환경오염 위험성'!H59
D35: ='③ 환경오염 위험성'!J59
C36: 운영 | D36: ='③ 환경오염 위험성'!F60
D37: ='③ 환경오염 위험성'!H60
D38: ='③ 환경오염 위험성'!J60
C39: 행정 | D39: ='③ 환경오염 위험성'!F61
D40: ='③ 환경오염 위험성'!H61
D41: ='③ 환경오염 위험성'!J61
B42: 작업자 안전보건 | C42: 공학 | D42: ='④ 작업자 안전보건'!F59
D43: ='④ 작업자 안전보건'!H59
D44: ='④ 작업자 안전보건'!J59
...

Sheet ⑥ 저감대책DB
A1: 화학물질 위험성 저감대책 DB
A2: 물리화학적/환경오염/작업자 안전보건 위험성평가 시, 적용할 위험도 저감대책을 DB형태로 제시 (사용자 저감대책 추가 가능)
B4: 📌 사용 안내 - ② ③ ④ 평가 시트의 저감대책 입력란에 적용할 저감대책의 'DB No.'(B열)를 입력하면 가능성 등급 감소량이 자동 적용됩니다. - 제어 위계 (강한 순) : 공학적(가중치 100%) → 운영적(가중치 75%) → 행정적(가중치 50%) → 보호구(가중치 50%) - 가능성 점수 감소치(E열) : -2~-3(원천 차단·밀폐류) / -1(부분 표준) / -0.5(보조·행정·보호구) - 저감대책 DB List는 필요시 사업 SHE부서에서 추가하여 운영 가능합니다 (목록 최하단 행에 양식에 맞추어 입력)
B5: DB No. | C5: 분야 | D5: 제어 위계 | E5: 가능성 점수 감소 | F5: 대책 내용 | G5: 주요 노출경로/관련 평가항목 | H5: (참고) 전제조건 및 주의사항
B6: PC-E-01 | C6: 물리화학 | D6: 공학 | E6: -3 | F6: 완전밀폐 자동화 시스템 (원격취급·로봇·자동공급) | G6: 전 항목 — 노출 경로 자체 차단 | H6: 초기 투자비 큼, 유지보수 SOP 필요, 비상정지기능 확보
B7: PC-E-02 | C7: 물리화학 | D7: 공학 | E7: -2 | F7: 부분 밀폐 시스템 (Glove box, Closed hood) | G7: 전 항목 — 작업자 접근 차단 | H7: 작업자 접근 통제, 누출 모니터링 병행
B8: PC-E-03 | C8: 물리화학 | D8: 공학 | E8: -2 | F8: 불활성가스(N₂/Ar) 봉입 저장·취급 시스템 | G8: ②자연발화, ⑤폭발·급분해 고위험 시 효과적 | H8: 산소농도 모니터링 필수, 질식위험 별도 관리
B9: PC-E-04 | C9: 물리화학 | D9: 공학 | E9: -2 | F9: 방폭전기설비 설치 (Zone 0/1/2 분류 준수) | G9: ⑦인화성, ⑧폭발성 고위험 시 효과적 | H9: KGS·KOSHA 방폭지침 준수, 정기 점검
B10: PC-E-05 | C10: 물리화학 | D10: 공학 | E10: -2 | F10: 자동 온도제어·냉장 보관 시스템 | G10: ②자연발화, ⑥저장 불안정 고위험 시 효과적 | H10: 온도 알람·기록 시스템, 정전 대비
B11: PC-E-06 | C11: 물리화학 | D11: 공학 | E11: -1 | F11: 정전기 방지 (접지·본딩·전도성 바닥) | G11: ⑦인화성, ⑧폭발성 보조 대책 | H11: 접지저항 정기측정
B12: PC-E-07 | C12: 물리화학 | D12: 공학 | E12: -2 | F12: 화재감지·자동소화 시스템 (포·CO₂·하론대체제) | G12: ⑦인화성, ⑧폭발성 고위험 시 효과적 | H12: 소화약제 호환성, 작업자 대피 우선
B13: PC-E-08 | C13: 물리화학 | D13: 공학 | E13: -2 | F13: 폭발방지 설계 (Rupture disc, PSV, 폭압방산구) | G13: ⑤폭발·급분해, ⑧산화성 고위험 시 효과적 | H13: 설정압력 정기점검, 배출유로 안전 확보
B14: PC-E-09 | C14: 물리화학 | D14: 공학 | E14: -1 | F14: 누액감지 센서 + 방류벽/방지턱(트렌치) | G14: 전 항목 — 누액 사고 방지 | H14: 누액감지 센서 설치, 정기 압력시험
B15: PC-E-10 | C15: 물리화학 | D15: 공학 | E15: -2 | F15: 자동 혼합 통제 인터록 (금기물질 자동 차단) | G15: ③혼합 위험 반응성 고위험 시 효과적 | H15: PLC 인터록 검증, 비상수동 차단 가능
B16: PC-E-11 | C16: 물리화학 | D16: 공학 | E16: -2 | F16: 가스 감지기 + 비상 셧다운 (LEL/UEL 감지) | G16: ④부산물, ⑦인화성 고위험 시 효과적 | H16: 25%LEL 경보, 50%LEL 셧다운 설정
B17: PC-E-12 | C17: 물리화학 | D17: 공학 | E17: -1 | F17: 충격·마찰 방지 용기·운반 (탄성소재·완충재) | G17: ⑤폭발·급분해 보조 대책 | H17: 운반로 평탄도 점검, 적재 높이 제한
... B89: OH-P-02 | C89: 작업자안전 | D89: 보호구 | E89: -1 | F89: 화학보호복+화학장갑+보안경+안전화 | G89: ②경구·경피, ③자극·부식 | H89: 재질 호환성표 확인, 손상시 폐기

Sheet (수정금지) 기준정보
B2: ■ 유해성 판단
B4: 항목 No. | C4: 항목명 | D4: H-Code | E4: 내용 | F4: 유해성 점수
B5: ②-7 | C5: 인화성 | D5: H220 | E5: 극인화성 가스 | F5: 5
D6: H222 | E6: 극인화성 에어로졸 | F6: 5
D7: H224 | E7: 극인화성 액체 및 증기 | F7: 5
D8: H221 | E8: 인화성 가스 | F8: 4
D9: H223 | E9: 인화성 에어로졸 | F9: 4
D10: H225 | E10: 고인화성 액체 및 증기 | F10: 4
D11: H228 | E11: 인화성 고체 | F11: 4
D12: H226 | E12: 인화성 액체 및 증기 | F12: 3
D13: H227 | E13: 가연성 액체 | F13: 2
D14: - | E14: 인화점 23℃ 미만, 끓는점 35℃ 이하 | F14: 5
D15: - | E15: 인화점 23℃ 미만, 끓는점 35℃ 초과 | F15: 4
D16: - | E16: 인화점 23℃ 이상 60℃ 미만 | F16: 3
D17: - | E17: 인화점 60℃ 이상 93℃ 미만 | F17: 2
... D19: - | E19: 인화점 없음 | F19: 1
B20: ②-5 | C20: 폭발·급분해 불안정성 | D20: H200 | E20: 불안정한 폭발성 물질 | F20: 5
D21: H201 | E21: 폭발성 물질; 대폭발 위험 | F21: 5
D22: H202 | E22: 폭발성 물질; 심한 분출 위험 | F22: 5
D23: H203 | E23: 폭발성 물질; 화재, 폭풍 또는 분출 위험 | F23: 5
D24: H204 | E24: 화재 또는 분출 위험 | F24: 5
D25: H205 | E25: 화재 시 대폭발 할 수 있음 | F25: 5
D26: H206 | E26: 화재, 폭발 또는 비산 위험; 둔감제 감소 시 폭발 위험성 증가 | F26: 4
D27: H240 | E27: 가열하면 폭발할 수 있음 | F27: 4
D28: H207 | E28: 화재 또는 비산 위험; 둔감제 감소 시 폭발 위험성이 증가함 | F28: 3
D29: H241 | E29: 가열하면 화재 또는 폭발할 수 있음 | F29: 3
D30: H208 | E30: 화재 또는 비산 위험; 둔감제 감소 시 폭발 위험성이 증가함 | F30: 2
D31: H242 | E31: 가열하면 화재를 일으킬 수 있음 | F31: 2
D32: - | E32: 분해온도 100℃ 미만 | F32: 4
... D36: - | E36: 분해온도 없음 | F36: 1
B37: ②-8 | C37: 폭발성·산화성 | D37: H200 | E37: 불안정한 폭발성 물질 | F37: 5
D38: H201 | E38: 폭발성 물질; 대폭발 위험 | F38: 5
D39: H202 | E39: 폭발성 물질; 심한 분출 위험 | F39: 5
D40: H203 | E40: 폭발성 물질; 화재, 폭풍 또는 분출 위험 | F40: 4
D41: H204 | E41: 화재 또는 분출 위험 | F41: 4
D42: H205 | E42: 화재 시 대폭발 할 수 있음 | F42: 4
D43: H270 | E43: 산화성 가스 | F43: 5
D44: H271 | E44: 산화성 액체/고체 Cat1 | F44: 4
D45: H272 | E45: 산화제 Cat2,3 | F45: 3
D46: - | E46: - | F46: 1
...
